Workbook
Name CONTRATOS_LISTA: 'Resumen_Cartera'!$A$5:$A$281

Sheet Caratula_Ejecutiva
B4: O-LEASING · UNA APP DE ORANGE CREW
B5: REPORTE INTEGRAL DE AUDITORÍA Y SALDOS DE CARTERA
B6: Normatividad NIF C-15 / IFRS 16 · Fórmulas Financieras Vivas de Excel · Desarrollado por Orange Crew · Ejercicio Fiscal 2026
B8: CONTRATOS AUDITADOS | D8: INVERSIÓN NETA TOTAL | F8: RENTA MENSUAL TOTAL | H8: RESIDUAL TOTAL PACTADO
B9: ='Resumen_Cartera'!G282 | D9: ='Resumen_Cartera'!K282 | F9: ='Resumen_Cartera'!N282 | H9: ='Resumen_Cartera'!P282
B10: TASA MENSUAL PROMEDIO | D10: TOTAL INTERÉS LEASING | F10: TOTAL INTERÉS RESIDUAL | H10: INGRESO FINANCIERO TOTAL
B11: ='Resumen_Cartera'!R282 | D11: ='Resumen_Cartera'!V282 | F11: ='Resumen_Cartera'!W282 | H11: ='Resumen_Cartera'!X282
B13: ÍNDICE DE HOJAS Y METODOLOGÍA DEL LIBRO OFICIAL (O-LEASING · ORANGE CREW)
B14: No. | C14: Hoja de Cálculo (Clic para ir) | D14: Propósito y Contenido Contable | E14: Fórmulas Matemáticas Clave
B15: 1 | C15: =HYPERLINK("#'Resumen_Cartera'!A1", "Resumen_Cartera") | D15: Padrón completo de contratos en vertical con unidad vehicular, porcentajes y rentabilidad. | E15: RATE, PV, SUM, AVERAGE
B16: 2 | C16: =HYPERLINK("#'Calculo_Tasa_Implicita'!A1", "Calculo_Tasa_Implicita") | D16: Metodología NIF C-15 / IFRS 16 de cálculo de tasa mensual y comprobación a diferencia cero. | E16: RATE, PV, Comprobación PV, TIR
B17: 3 | C17: =HYPERLINK("#'Modelo_Amortizacion_Tipo'!A1", "Modelo_Amortizacion_Tipo") | D17: Demostración dinámica con selector desplegable de contrato y corte automático exacto al plazo. | E17: VLOOKUP, Saldo*Tasa, Renta-Interés, Corte
B18: 4 | C18: =HYPERLINK("#'Intereses_Leasing_Mensual'!A1", "Intereses_Leasing_Mensual") | D18: Matriz horizontal de intereses de leasing devengados mes a mes por contrato. | E18: IF(Saldo_Ant>0, ROUND(Saldo_Ant*Tasa, 2), '')
B19: 5 | C19: =HYPERLINK("#'Intereses_Residual_Mensual'!A1", "Intereses_Residual_Mensual") | D19: Matriz horizontal de intereses sobre el valor presente del residual (NIF C-15). | E19: IF(Saldo_Res_Ant>0, ROUND(Saldo_Res*Tasa, 2), '')
B20: 6 | C20: =HYPERLINK("#'Ingreso_Financiero_Total'!A1", "Ingreso_Financiero_Total") | D20: Matriz de ingreso financiero consolidado (Leasing + Residual) mes a mes. | E20: Intereses_Leasing_Mensual! + Residual!
B21: 7 | C21: =HYPERLINK("#'Amortizacion_Capital_Mensual'!A1", "Amortizacion_Capital_Mensual") | D21: Matriz horizontal de amortización de principal mes a mes. | E21: IF(Leasing>0, Renta - Leasing, '')
B22: 8 | C22: =HYPERLINK("#'Saldos_Capital_Mensual'!A1", "Saldos_Capital_Mensual") | D22: Saldo insoluto de principal mes a mes al cierre de cada periodo contable. | E22: IF(Cap>0, Saldo_Ant - Cap, '')
B23: 9 | C23: =HYPERLINK("#'Saldos_Intereses_Mensual'!A1", "Saldos_Intereses_Mensual") | D23: Saldo de intereses remanentes por devengar/cobrar desde cada corte mensual. | E23: IF(Int>0, Saldo_Ant - Int, '')
B24: 10 | C24: =HYPERLINK("#'Saldos_Cartera_Total'!A1", "Saldos_Cartera_Total") | D24: Saldo total exigible de mensualidades restantes (Capital + Intereses). | E24: Saldos_Capital! + Saldos_Intereses!
B25: 11 | C25: =HYPERLINK("#'Saldo_Residual_Activo'!A1", "Saldo_Residual_Activo") | D25: Evolución mensual del saldo activo del valor residual pactado. | E25: IF(Int_Res>0, Saldo_Ant + Int_Res, '')
B26: 12 | C26: =HYPERLINK("#'Saldos_Exigible_Global'!A1", "Saldos_Exigible_Global") | D26: Deuda integral total de cartera más valor residual activo. | E26: Saldos_Cartera_Total! + Saldo_Residual!
B27: 13 | C27: =HYPERLINK("#'Matriz_Consolidada'!A1", "Matriz_Consolidada") | D27: Bloques cronológicos multi-concepto con leasing, residual, ingreso y capital de cartera. | E27: Fórmulas inter-hoja vivas
B28: 14 | C28: =HYPERLINK("#'Matriz_Consolidada_Saldos'!A1", "Matriz_Consolidada_Saldos") | D28: Bloques cronológicos multi-concepto con los 5 rubros de saldos lado a lado. | E28: Fórmulas inter-hoja vivas
B30: O-LEASING es una aplicación financiera desarrollada y mantenida por ORANGE CREW. Todos los derechos reservados conforme a la LFDA.

Sheet Resumen_Cartera
A1: O-LEASING · UNA APP DE ORANGE CREW · Resumen de Cartera y Parámetros Financieros
A2: Parámetros contractuales, unidad adquirida, porcentajes iniciales y fórmulas matemáticas de rentabilidad · Auditoría Financiera NIF C-15 / IFRS 16 · Desarrollado por Orange Crew
A4: ID_Contrato | B4: Cliente | C4: Vehiculo | D4: Estatus | E4: Fecha_Alta | F4: Fecha_Vencimiento | G4: Plazo_Meses | H4: Valor_Sin_IVA | I4: Anticipo_Pct | J4: Anticipo_Monto | K4: Inversion_Neta | L4: Comision_Pct | M4: Comision_Apertura | N4: Renta_Sin_IVA | O4: Residual_Pct | P4: Residual_Pactado | Q4: Tasa_Mensual_Reg | R4: Tasa_Mensual_RATE | S4: Tasa_Nominal_Anual | T4: TIR_Anual_Efectiva | U4: VP_Residual | V4: Total_Interes_Leasing | W4: Total_Interes_Residual | X4: Ingreso_Financiero_Total | Y4: Ganancia_Neta | Z4: Margen_Sobre_Inv
A5: 0326-0003 | B5: Alberto Vázquez Solorio | C5: Volkswagen Tiguan R-Line 2026 | D5: ACTIVO | E5: 2026-09-16 | F5: 2030-09-16 | G5: 48 | H5: 645181.9 | I5: 0.3705 | J5: =ROUND(H5*I5, 2) | K5: =ROUND(H5-J5, 2) | L5: 0 | M5: =ROUND(H5*L5, 2) | N5: 8393.91 | O5: 0.28 | P5: =ROUND(H5*O5, 2) | Q5: 0.01206146 | R5: =IFERROR(RATE(G5, -N5, K5, -P5), Q5) | S5: =Q5*12 | T5: =((1+Q5)^12)-1 | U5: =IF(Q5>0, ROUND(P5/((1+Q5)^G5), 2), P5) | V5: =ROUND((N5*G5)-K5+P5, 2) | W5: =ROUND(P5-U5, 2) | X5: =ROUND(V5+W5, 2) | Y5: =ROUND((N5*G5+P5+M5)-K5, 2) | Z5: =IF(K5>0, Y5/K5, 0)
A6: 0472-0003 | B6: Miguel Zazueta Beltrán | C6: Jeep Grand Cherokee | D6: ACTIVO | E6: 2026-02-03 | F6: 2029-02-03 | G6: 36 | H6: 1217433.6 | I6: 0.3 | J6: =ROUND(H6*I6, 2) | K6: =ROUND(H6-J6, 2) | L6: 0.02 | M6: =ROUND(H6*L6, 2) | N6: 35031.5 | O6: 0.1 | P6: =ROUND(H6*O6, 2) | Q6: 0.02661776 | R6: =IFERROR(RATE(G6, -N6, K6, -P6), Q6) | S6: =Q6*12 | T6: =((1+Q6)^12)-1 | U6: =IF(Q6>0, ROUND(P6/((1+Q6)^G6), 2), P6) | V6: =ROUND((N6*G6)-K6+P6, 2) | W6: =ROUND(P6-U6, 2) | X6: =ROUND(V6+W6, 2) | Y6: =ROUND((N6*G6+P6+M6)-K6, 2) | Z6: =IF(K6>0, Y6/K6, 0)
A7: 0504-0004 | B7: Oscar Ivan Lozano Terriquez | C7: 700 BIGHORN "S" CREW CAB MT | D7: ACTIVO | E7: 2026-01-05 | F7: 2027-01-05 | G7: 12 | H7: 352500 | I7: 0.35 | J7: =ROUND(H7*I7, 2) | K7: =ROUND(H7-J7, 2) | L7: 0.02 | M7: =ROUND(H7*L7, 2) | N7: 19654.64 | O7: 0.1 | P7: =ROUND(H7*O7, 2) | Q7: 0.02415117 | R7: =IFERROR(RATE(G7, -N7, K7, -P7), Q7) | S7: =Q7*12 | T7: =((1+Q7)^12)-1 | U7: =IF(Q7>0, ROUND(P7/((1+Q7)^G7), 2), P7) | V7: =ROUND((N7*G7)-K7+P7, 2) | W7: =ROUND(P7-U7, 2) | X7: =ROUND(V7+W7, 2) | Y7: =ROUND((N7*G7+P7+M7)-K7, 2) | Z7: =IF(K7>0, Y7/K7, 0)
A8: 0506-0006 | B8: Electronic Accounting Sa de Cv | C8: X5 | D8: ACTIVO | E8: 2024-01-10 | F8: 2027-01-10 | G8: 36 | H8: 1622338.8 | I8: 0.1759 | J8: =ROUND(H8*I8, 2) | K8: =ROUND(H8-J8, 2) | L8: 0 | M8: =ROUND(H8*L8, 2) | N8: 35607.45 | O8: 0.35 | P8: =ROUND(H8*O8, 2) | Q8: 0.01430392 | R8: =IFERROR(RATE(G8, -N8, K8, -P8), Q8) | S8: =Q8*12 | T8: =((1+Q8)^12)-1 | U8: =IF(Q8>0, ROUND(P8/((1+Q8)^G8), 2), P8) | V8: =ROUND((N8*G8)-K8+P8, 2) | W8: =ROUND(P8-U8, 2) | X8: =ROUND(V8+W8, 2) | Y8: =ROUND((N8*G8+P8+M8)-K8, 2) | Z8: =IF(K8>0, Y8/K8, 0)
A9: 0506-0007 | B9: Electronic Acounting | C9: L200 Glx Diesel | D9: ACTIVO | E9: 2024-09-05 | F9: 2027-09-05 | G9: 36 | H9: 536762.93 | I9: 0 | J9: =ROUND(H9*I9, 2) | K9: =ROUND(H9-J9, 2) | L9: 0 | M9: =ROUND(H9*L9, 2) | N9: 16715.69 | O9: 0.35 | P9: =ROUND(H9*O9, 2) | Q9: 0.01820217 | R9: =IFERROR(RATE(G9, -N9, K9, -P9), Q9) | S9: =Q9*12 | T9: =((1+Q9)^12)-1 | U9: =IF(Q9>0, ROUND(P9/((1+Q9)^G9), 2), P9) | V9: =ROUND((N9*G9)-K9+P9, 2) | W9: =ROUND(P9-U9, 2) | X9: =ROUND(V9+W9, 2) | Y9: =ROUND((N9*G9+P9+M9)-K9, 2) | Z9: =IF(K9>0, Y9/K9, 0)
A10: 0519-0005 | B10: Tequilas el Mexicano S.A. de C.V. | C10: Attitude Sport | D10: ACTIVO | E10: 2025-07-14 | F10: 2029-07-14 | G10: 48 | H10: 352500 | I10: 0.1 | J10: =ROUND(H10*I10, 2) | K10: =ROUND(H10-J10, 2) | L10: 0 | M10: =ROUND(H10*L10, 2) | N10: 11483.47 | O10: 0.1 | P10: =ROUND(H10*O10, 2) | Q10: 0.02691789 | R10: =IFERROR(RATE(G10, -N10, K10, -P10), Q10) | S10: =Q10*12 | T10: =((1+Q10)^12)-1 | U10: =IF(Q10>0, ROUND(P10/((1+Q10)^G10), 2), P10) | V10: =ROUND((N10*G10)-K10+P10, 2) | W10: =ROUND(P10-U10, 2) | X10: =ROUND(V10+W10, 2) | Y10: =ROUND((N10*G10+P10+M10)-K10, 2) | Z10: =IF(K10>0, Y10/K10, 0)
A11: 0520-0003 | B11: Tractomotriz Diesel Leal, S.A. de C.V. | C11: Montero Sport | D11: ACTIVO | E11: 2025-11-28 | F11: 2028-11-28 | G11: 36 | H11: 621465.52 | I11: 0.4 | J11: =ROUND(H11*I11, 2) | K11: =ROUND(H11-J11, 2) | L11: 1 | M11: =ROUND(H11*L11, 2) | N11: 15182.88 | O11: 0.1 | P11: =ROUND(H11*O11, 2) | Q11: 0.02663641 | R11: =IFERROR(RATE(G11, -N11, K11, -P11), Q11) | S11: =Q11*12 | T11: =((1+Q11)^12)-1 | U11: =IF(Q11>0, ROUND(P11/((1+Q11)^G11), 2), P11) | V11: =ROUND((N11*G11)-K11+P11, 2) | W11: =ROUND(P11-U11, 2) | X11: =ROUND(V11+W11, 2) | Y11: =ROUND((N11*G11+P11+M11)-K11, 2) | Z11: =IF(K11>0, Y11/K11, 0)
A12: 0520-0004 | B12: Tractomotriz Diesel Leal, S.A. de C.V. | C12: Partner Maxi Pack | D12: ACTIVO | E12: 2025-12-04 | F12: 2028-12-04 | G12: 36 | H12: 400363.79 | I12: 0.4 | J12: =ROUND(H12*I12, 2) | K12: =ROUND(H12-J12, 2) | L12: 1 | M12: =ROUND(H12*L12, 2) | N12: 9781.2 | O12: 0.1 | P12: =ROUND(H12*O12, 2) | Q12: 0.02663643 | R12: =IFERROR(RATE(G12, -N12, K12, -P12), Q12) | S12: =Q12*12 | T12: =((1+Q12)^12)-1 | U12: =IF(Q12>0, ROUND(P12/((1+Q12)^G12), 2), P12) | V12: =ROUND((N12*G12)-K12+P12, 2) | W12: =ROUND(P12-U12, 2) | X12: =ROUND(V12+W12, 2) | Y12: =ROUND((N12*G12+P12+M12)-K12, 2) | Z12: =IF(K12>0, Y12/K12, 0)
A13: 0521-0002 | B13: Carlos Hiram leal Leal | C13: Xpander | D13: ACTIVO | E13: 2025-09-08 | F13: 2028-09-08 | G13: 36 | H13: 365988.79 | I13: 0.1 | J13: =ROUND(H13*I13, 2) | K13: =ROUND(H13-J13, 2) | L13: 1 | M13: =ROUND(H13*L13, 2) | N13: 13100.96 | O13: 0.2 | P13: =ROUND(H13*O13, 2) | Q13: 0.02662861 | R13: =IFERROR(RATE(G13, -N13, K13, -P13), Q13) | S13: =Q13*12 | T13: =((1+Q13)^12)-1 | U13: =IF(Q13>0, ROUND(P13/((1+Q13)^G13), 2), P13) | V13: =ROUND((N13*G13)-K13+P13, 2) | W13: =ROUND(P13-U13, 2) | X13: =ROUND(V13+W13, 2) | Y13: =ROUND((N13*G13+P13+M13)-K13, 2) | Z13: =IF(K13>0, Y13/K13, 0)
A14: 0524-0007 | B14: Lider En Derecho De Via y Construcción SA DE CV | C14: L200 Gls | D14: ACTIVO | E14: 2025-08-15 | F14: 2027-08-15 | G14: 24 | H14: 649987.07 | I14: 0.1 | J14: =ROUND(H14*I14, 2) | K14: =ROUND(H14-J14, 2) | L14: 0 | M14: =ROUND(H14*L14, 2) | N14: 27206.74 | O14: 0.3 | P14: =ROUND(H14*O14, 2) | Q14: 0.02620493 | R14: =IFERROR(RATE(G14, -N14, K14, -P14), Q14) | S14: =Q14*12 | T14: =((1+Q14)^12)-1 | U14: =IF(Q14>0, ROUND(P14/((1+Q14)^G14), 2), P14) | V14: =ROUND((N14*G14)-K14+P14, 2) | W14: =ROUND(P14-U14, 2) | X14: =ROUND(V14+W14, 2) | Y14: =ROUND((N14*G14+P14+M14)-K14, 2) | Z14: =IF(K14>0, Y14/K14, 0)
A15: 0524-0011 | B15: Lider En Derecho De Via y Construcción SA DE CV | C15: Wrangler Unlimited Sahara | D15: ACTIVO | E15: 2025-12-31 | F15: 2029-12-31 | G15: 48 | H15: 1058554.3 | I15: 0.2 | J15: =ROUND(H15*I15, 2) | K15: =ROUND(H15-J15, 2) | L15: 0.02 | M15: =ROUND(H15*L15, 2) | N15: 30510.75 | O15: 0.1 | P15: =ROUND(H15*O15, 2) | Q15: 0.0268869 | R15: =IFERROR(RATE(G15, -N15, K15, -P15), Q15) | S15: =Q15*12 | T15: =((1+Q15)^12)-1 | U15: =IF(Q15>0, ROUND(P15/((1+Q15)^G15), 2), P15) | V15: =ROUND((N15*G15)-K15+P15, 2) | W15: =ROUND(P15-U15, 2) | X15: =ROUND(V15+W15, 2) | Y15: =ROUND((N15*G15+P15+M15)-K15, 2) | Z15: =IF(K15>0, Y15/K15, 0)
A16: 0524-0012 | B16: Lider En Derecho De Via y Construcción SA DE CV | C16: L200 GLS | D16: ACTIVO | E16: 2026-03-17 | F16: 2030-03-17 | G16: 48 | H16: 624154.31 | I16: 0.1 | J16: =ROUND(H16*I16, 2) | K16: =ROUND(H16-J16, 2) | L16: 0.02 | M16: =ROUND(H16*L16, 2) | N16: 20333.22 | O16: 0.1 | P16: =ROUND(H16*O16, 2) | Q16: 0.0269179 | R16: =IFERROR(RATE(G16, -N16, K16, -P16), Q16) | S16: =Q16*12 | T16: =((1+Q16)^12)-1 | U16: =IF(Q16>0, ROUND(P16/((1+Q16)^G16), 2), P16) | V16: =ROUND((N16*G16)-K16+P16, 2) | W16: =ROUND(P16-U16, 2) | X16: =ROUND(V16+W16, 2) | Y16: =ROUND((N16*G16+P16+M16)-K16, 2) | Z16: =IF(K16>0, Y16/K16, 0)
... A281: 0786-0001 | B281: Consejería Jurídico Empresarial, S.C. | C281: Mitsubishi Outlander Sport Limited 2027 | D281: ACTIVO | E281: 2026-09-28 | F281: 2028-09-28 | G281: 24 | H281: 475727.59 | I281: 0.3 | J281: =ROUND(H281*I281, 2) | K281: =ROUND(H281-J281, 2) | L281: 0.02 | M281: =ROUND(H281*L281, 2) | N281: 15957.97 | O281: 0.2 | P281: =ROUND(H281*O281, 2) | Q281: 0.02615301 | R281: =IFERROR(RATE(G281, -N281, K281, -P281), Q281) | S281: =Q281*12 | T281: =((1+Q281)^12)-1 | U281: =IF(Q281>0, ROUND(P281/((1+Q281)^G281), 2), P281) | V281: =ROUND((N281*G281)-K281+P281, 2) | W281: =ROUND(P281-U281, 2) | X281: =ROUND(V281+W281, 2) | Y281: =ROUND((N281*G281+P281+M281)-K281, 2) | Z281: =IF(K281>0, Y281/K281, 0)
A282: TOTAL CARTERA | B282: 277 Contratos Registrados | H282: =SUM(H5:H281) | I282: =AVERAGE(I5:I281) | J282: =SUM(J5:J281) | K282: =SUM(K5:K281) | L282: =AVERAGE(L5:L281) | M282: =SUM(M5:M281) | N282: =SUM(N5:N281) | O282: =AVERAGE(O5:O281) | P282: =SUM(P5:P281) | Q282: =AVERAGE(Q5:Q281) | R282: =AVERAGE(R5:R281) | S282: =AVERAGE(S5:S281) | T282: =AVERAGE(T5:T281) | U282: =SUM(U5:U281) | V282: =SUM(V5:V281) | W282: =SUM(W5:W281) | X282: =SUM(X5:X281) | Y282: =SUM(Y5:Y281) | Z282: =IF(K282>0, Y282/K282, 0)

Sheet Calculo_Tasa_Implicita
A1: O-LEASING · UNA APP DE ORANGE CREW · Cálculo de Tasa Implícita y Comprobación de Flujos (NIF C-15 / IFRS 16)
A2: Determinación de tasa mensual mediante RATE(nper, -pmt, pv, -fv), unidad adquirida y comprobación PV con diferencia cero · Auditoría Financiera NIF C-15 / IFRS 16 · Desarrollado por Orange Crew
A4: ID_Contrato | B4: Cliente | C4: Vehiculo | D4: Estatus | E4: Plazo_Meses | F4: Valor_Sin_IVA | G4: Anticipo_Pct | H4: Anticipo_Monto | I4: Inversion_Neta | J4: Renta_Sin_IVA | K4: Residual_Pct | L4: Residual_Pactado | M4: Tasa_Mensual_Registrada | N4: Tasa_Calculada_RATE | O4: Comprobacion_PV | P4: Diferencia_Cuadre | Q4: Tasa_Nominal_Anual | R4: TIR_Anual_Efectiva | S4: Diferencia_vs_Registrada | T4: Estatus_Verificacion
A5: 0326-0003 | B5: Alberto Vázquez Solorio | C5: Volkswagen Tiguan R-Line 2026 | D5: ACTIVO | E5: 48 | F5: 645181.9 | G5: 0.3705 | H5: =ROUND(F5*G5, 2) | I5: =ROUND(F5-H5, 2) | J5: 8393.91 | K5: 0.28 | L5: =ROUND(F5*K5, 2) | M5: 0.01206146 | N5: =IFERROR(RATE(E5, -J5, I5, -L5), M5) | O5: =IF(N5>0, ROUND(PV(N5, E5, -J5, -L5), 2), I5) | P5: =ROUND(O5-I5, 2) | Q5: =N5*12 | R5: =((1+N5)^12)-1 | S5: =N5-M5 | T5: =IF(ABS(P5)<0.01, "EXACTO", "REVISAR")
A6: 0472-0003 | B6: Miguel Zazueta Beltrán | C6: Jeep Grand Cherokee | D6: ACTIVO | E6: 36 | F6: 1217433.6 | G6: 0.3 | H6: =ROUND(F6*G6, 2) | I6: =ROUND(F6-H6, 2) | J6: 35031.5 | K6: 0.1 | L6: =ROUND(F6*K6, 2) | M6: 0.02661776 | N6: =IFERROR(RATE(E6, -J6, I6, -L6), M6) | O6: =IF(N6>0, ROUND(PV(N6, E6, -J6, -L6), 2), I6) | P6: =ROUND(O6-I6, 2) | Q6: =N6*12 | R6: =((1+N6)^12)-1 | S6: =N6-M6 | T6: =IF(ABS(P6)<0.01, "EXACTO", "REVISAR")
A7: 0504-0004 | B7: Oscar Ivan Lozano Terriquez | C7: 700 BIGHORN "S" CREW CAB MT | D7: ACTIVO | E7: 12 | F7: 352500 | G7: 0.35 | H7: =ROUND(F7*G7, 2) | I7: =ROUND(F7-H7, 2) | J7: 19654.64 | K7: 0.1 | L7: =ROUND(F7*K7, 2) | M7: 0.02415117 | N7: =IFERROR(RATE(E7, -J7, I7, -L7), M7) | O7: =IF(N7>0, ROUND(PV(N7, E7, -J7, -L7), 2), I7) | P7: =ROUND(O7-I7, 2) | Q7: =N7*12 | R7: =((1+N7)^12)-1 | S7: =N7-M7 | T7: =IF(ABS(P7)<0.01, "EXACTO", "REVISAR")
A8: 0506-0006 | B8: Electronic Accounting Sa de Cv | C8: X5 | D8: ACTIVO | E8: 36 | F8: 1622338.8 | G8: 0.1759 | H8: =ROUND(F8*G8, 2) | I8: =ROUND(F8-H8, 2) | J8: 35607.45 | K8: 0.35 | L8: =ROUND(F8*K8, 2) | M8: 0.01430392 | N8: =IFERROR(RATE(E8, -J8, I8, -L8), M8) | O8: =IF(N8>0, ROUND(PV(N8, E8, -J8, -L8), 2), I8) | P8: =ROUND(O8-I8, 2) | Q8: =N8*12 | R8: =((1+N8)^12)-1 | S8: =N8-M8 | T8: =IF(ABS(P8)<0.01, "EXACTO", "REVISAR")
A9: 0506-0007 | B9: Electronic Acounting | C9: L200 Glx Diesel | D9: ACTIVO | E9: 36 | F9: 536762.93 | G9: 0 | H9: =ROUND(F9*G9, 2) | I9: =ROUND(F9-H9, 2) | J9: 16715.69 | K9: 0.35 | L9: =ROUND(F9*K9, 2) | M9: 0.01820217 | N9: =IFERROR(RATE(E9, -J9, I9, -L9), M9) | O9: =IF(N9>0, ROUND(PV(N9, E9, -J9, -L9), 2), I9) | P9: =ROUND(O9-I9, 2) | Q9: =N9*12 | R9: =((1+N9)^12)-1 | S9: =N9-M9 | T9: =IF(ABS(P9)<0.01, "EXACTO", "REVISAR")
A10: 0519-0005 | B10: Tequilas el Mexicano S.A. de C.V. | C10: Attitude Sport | D10: ACTIVO | E10: 48 | F10: 352500 | G10: 0.1 | H10: =ROUND(F10*G10, 2) | I10: =ROUND(F10-H10, 2) | J10: 11483.47 | K10: 0.1 | L10: =ROUND(F10*K10, 2) | M10: 0.02691789 | N10: =IFERROR(RATE(E10, -J10, I10, -L10), M10) | O10: =IF(N10>0, ROUND(PV(N10, E10, -J10, -L10), 2), I10) | P10: =ROUND(O10-I10, 2) | Q10: =N10*12 | R10: =((1+N10)^12)-1 | S10: =N10-M10 | T10: =IF(ABS(P10)<0.01, "EXACTO", "REVISAR")
A11: 0520-0003 | B11: Tractomotriz Diesel Leal, S.A. de C.V. | C11: Montero Sport | D11: ACTIVO | E11: 36 | F11: 621465.52 | G11: 0.4 | H11: =ROUND(F11*G11, 2) | I11: =ROUND(F11-H11, 2) | J11: 15182.88 | K11: 0.1 | L11: =ROUND(F11*K11, 2) | M11: 0.02663641 | N11: =IFERROR(RATE(E11, -J11, I11, -L11), M11) | O11: =IF(N11>0, ROUND(PV(N11, E11, -J11, -L11), 2), I11) | P11: =ROUND(O11-I11, 2) | Q11: =N11*12 | R11: =((1+N11)^12)-1 | S11: =N11-M11 | T11: =IF(ABS(P11)<0.01, "EXACTO", "REVISAR")
A12: 0520-0004 | B12: Tractomotriz Diesel Leal, S.A. de C.V. | C12: Partner Maxi Pack | D12: ACTIVO | E12: 36 | F12: 400363.79 | G12: 0.4 | H12: =ROUND(F12*G12, 2) | I12: =ROUND(F12-H12, 2) | J12: 9781.2 | K12: 0.1 | L12: =ROUND(F12*K12, 2) | M12: 0.02663643 | N12: =IFERROR(RATE(E12, -J12, I12, -L12), M12) | O12: =IF(N12>0, ROUND(PV(N12, E12, -J12, -L12), 2), I12) | P12: =ROUND(O12-I12, 2) | Q12: =N12*12 | R12: =((1+N12)^12)-1 | S12: =N12-M12 | T12: =IF(ABS(P12)<0.01, "EXACTO", "REVISAR")
A13: 0521-0002 | B13: Carlos Hiram leal Leal | C13: Xpander | D13: ACTIVO | E13: 36 | F13: 365988.79 | G13: 0.1 | H13: =ROUND(F13*G13, 2) | I13: =ROUND(F13-H13, 2) | J13: 13100.96 | K13: 0.2 | L13: =ROUND(F13*K13, 2) | M13: 0.02662861 | N13: =IFERROR(RATE(E13, -J13, I13, -L13), M13) | O13: =IF(N13>0, ROUND(PV(N13, E13, -J13, -L13), 2), I13) | P13: =ROUND(O13-I13, 2) | Q13: =N13*12 | R13: =((1+N13)^12)-1 | S13: =N13-M13 | T13: =IF(ABS(P13)<0.01, "EXACTO", "REVISAR")
A14: 0524-0007 | B14: Lider En Derecho De Via y Construcción SA DE CV | C14: L200 Gls | D14: ACTIVO | E14: 24 | F14: 649987.07 | G14: 0.1 | H14: =ROUND(F14*G14, 2) | I14: =ROUND(F14-H14, 2) | J14: 27206.74 | K14: 0.3 | L14: =ROUND(F14*K14, 2) | M14: 0.02620493 | N14: =IFERROR(RATE(E14, -J14, I14, -L14), M14) | O14: =IF(N14>0, ROUND(PV(N14, E14, -J14, -L14), 2), I14) | P14: =ROUND(O14-I14, 2) | Q14: =N14*12 | R14: =((1+N14)^12)-1 | S14: =N14-M14 | T14: =IF(ABS(P14)<0.01, "EXACTO", "REVISAR")
A15: 0524-0011 | B15: Lider En Derecho De Via y Construcción SA DE CV | C15: Wrangler Unlimited Sahara | D15: ACTIVO | E15: 48 | F15: 1058554.3 | G15: 0.2 | H15: =ROUND(F15*G15, 2) | I15: =ROUND(F15-H15, 2) | J15: 30510.75 | K15: 0.1 | L15: =ROUND(F15*K15, 2) | M15: 0.0268869 | N15: =IFERROR(RATE(E15, -J15, I15, -L15), M15) | O15: =IF(N15>0, ROUND(PV(N15, E15, -J15, -L15), 2), I15) | P15: =ROUND(O15-I15, 2) | Q15: =N15*12 | R15: =((1+N15)^12)-1 | S15: =N15-M15 | T15: =IF(ABS(P15)<0.01, "EXACTO", "REVISAR")
A16: 0524-0012 | B16: Lider En Derecho De Via y Construcción SA DE CV | C16: L200 GLS | D16: ACTIVO | E16: 48 | F16: 624154.31 | G16: 0.1 | H16: =ROUND(F16*G16, 2) | I16: =ROUND(F16-H16, 2) | J16: 20333.22 | K16: 0.1 | L16: =ROUND(F16*K16, 2) | M16: 0.0269179 | N16: =IFERROR(RATE(E16, -J16, I16, -L16), M16) | O16: =IF(N16>0, ROUND(PV(N16, E16, -J16, -L16), 2), I16) | P16: =ROUND(O16-I16, 2) | Q16: =N16*12 | R16: =((1+N16)^12)-1 | S16: =N16-M16 | T16: =IF(ABS(P16)<0.01, "EXACTO", "REVISAR")
... A281: 0786-0001 | B281: Consejería Jurídico Empresarial, S.C. | C281: Mitsubishi Outlander Sport Limited 2027 | D281: ACTIVO | E281: 24 | F281: 475727.59 | G281: 0.3 | H281: =ROUND(F281*G281, 2) | I281: =ROUND(F281-H281, 2) | J281: 15957.97 | K281: 0.2 | L281: =ROUND(F281*K281, 2) | M281: 0.02615301 | N281: =IFERROR(RATE(E281, -J281, I281, -L281), M281) | O281: =IF(N281>0, ROUND(PV(N281, E281, -J281, -L281), 2), I281) | P281: =ROUND(O281-I281, 2) | Q281: =N281*12 | R281: =((1+N281)^12)-1 | S281: =N281-M281 | T281: =IF(ABS(P281)<0.01, "EXACTO", "REVISAR")
A282: TOTAL CARTERA | B282: 277 Contratos | F282: =SUM(F5:F281) | G282: =AVERAGE(G5:G281) | H282: =SUM(H5:H281) | I282: =SUM(I5:I281) | J282: =SUM(J5:J281) | K282: =AVERAGE(K5:K281) | L282: =SUM(L5:L281) | M282: =AVERAGE(M5:M281) | N282: =AVERAGE(N5:N281) | O282: =SUM(O5:O281) | P282: =SUM(P5:P281) | Q282: =AVERAGE(Q5:Q281) | R282: =AVERAGE(R5:R281) | S282: =AVERAGE(S5:S281) | T282: AUDITADO

Sheet Modelo_Amortizacion_Tipo
A1: O-LEASING · UNA APP DE ORANGE CREW · Modelo de Amortización Dinámica con Fórmulas Nativas
A2: Seleccione cualquier contrato en la lista desplegable; la tabla actualiza todos los datos y se corta al mes exacto de terminación · Auditoría Financiera NIF C-15 / IFRS 16 · Desarrollado por Orange Crew
B4: SELECCIONAR CONTRATO: | C4: 0326-0003 | D4: <-- Seleccione de la lista desplegable o escriba el ID del contrato para actualizar toda la tabla
B5: Cliente: | C5: =IFERROR(VLOOKUP($C$4, 'Resumen_Cartera'!$A$5:$Z$281, 2, FALSE), "") | F5: Unidad / Vehículo: | G5: =IFERROR(VLOOKUP($C$4, 'Resumen_Cartera'!$A$5:$Z$281, 3, FALSE), "") | J5: Estatus: | K5: =IFERROR(VLOOKUP($C$4, 'Resumen_Cartera'!$A$5:$Z$281, 4, FALSE), "")
B6: Fecha Alta: | C6: =IFERROR(VLOOKUP($C$4, 'Resumen_Cartera'!$A$5:$Z$281, 5, FALSE), "") | D6: Fecha Vencimiento: | E6: =IFERROR(VLOOKUP($C$4, 'Resumen_Cartera'!$A$5:$Z$281, 6, FALSE), "") | F6: Plazo (Meses): | G6: =IFERROR(VLOOKUP($C$4, 'Resumen_Cartera'!$A$5:$Z$281, 7, FALSE), 0) | H6: Valor Sin IVA: | I6: =IFERROR(VLOOKUP($C$4, 'Resumen_Cartera'!$A$5:$Z$281, 8, FALSE), 0)
B7: Inversión Neta: | C7: =IFERROR(VLOOKUP($C$4, 'Resumen_Cartera'!$A$5:$Z$281, 11, FALSE), 0) | D7: Renta Mensual: | E7: =IFERROR(VLOOKUP($C$4, 'Resumen_Cartera'!$A$5:$Z$281, 14, FALSE), 0) | F7: Residual Pactado: | G7: =IFERROR(VLOOKUP($C$4, 'Resumen_Cartera'!$A$5:$Z$281, 16, FALSE), 0) | H7: VP Residual Inicial: | I7: =IFERROR(VLOOKUP($C$4, 'Resumen_Cartera'!$A$5:$Z$281, 21, FALSE), 0)
B8: Tasa Mensual: | C8: =IFERROR(VLOOKUP($C$4, 'Resumen_Cartera'!$A$5:$Z$281, 17, FALSE), 0) | D8: Tasa Nominal Anual: | E8: =IFERROR(VLOOKUP($C$4, 'Resumen_Cartera'!$A$5:$Z$281, 19, FALSE), 0) | F8: TIR Anual Efectiva: | G8: =IFERROR(VLOOKUP($C$4, 'Resumen_Cartera'!$A$5:$Z$281, 20, FALSE), 0) | H8: Ingreso Financiero: | I8: =IFERROR(VLOOKUP($C$4, 'Resumen_Cartera'!$A$5:$Z$281, 24, FALSE), 0)
A9: FÓRMULAS VIVAS DE AMORTIZACIÓN Y SALDOS: Interés = Saldo_Inicial * Tasa | Capital = Renta - Interés | Saldo Capital = Saldo_Inicial - Capital | Interés Residual = VP_Residual * Tasa | VP_Residual_Final = VP_Inicial + Interés_Residual | Saldo Intereses = SUM(Futuros) | Saldo Cartera = Saldo_Capital + Saldo_Intereses | Saldo Global = Saldo_Cartera + VP_Residual. La tabla se corta automáticamente al plazo contractual ($G$6 meses).
A10: Mes | B10: Saldo_Inicial_Capital | C10: Tasa_Mensual | D10: Interes_Leasing | E10: Renta_Sin_IVA | F10: Capital_Amortizado | G10: Saldo_Final_Capital | H10: VP_Residual_Inicial | I10: Interes_Residual | J10: VP_Residual_Final | K10: Ingreso_Financiero_Total | L10: Saldo_Intereses_Remanentes | M10: Saldo_Cartera_Total | N10: Saldo_Global_Exigible
A11: =IF(ROW()-10<=$G$6, ROW()-10, "") | B11: =IF($A11="", "", $C$7) | C11: =IF($A11="", "", $C$8) | D11: =IF($A11="", "", ROUND(B11*C11, 2)) | E11: =IF($A11="", "", $E$7) | F11: =IF($A11="", "", E11-D11) | G11: =IF($A11="", "", B11-F11) | H11: =IF($A11="", "", $I$7) | I11: =IF($A11="", "", ROUND(H11*C11, 2)) | J11: =IF($A11="", "", H11+I11) | K11: =IF($A11="", "", D11+I11) | L11: =IF($A11="", "", SUM(D12:$D$82)) | M11: =IF($A11="", "", G11+L11) | N11: =IF($A11="", "", M11+J11)
A12: =IF(ROW()-10<=$G$6, ROW()-10, "") | B12: =IF($A12="", "", G11) | C12: =IF($A12="", "", $C$8) | D12: =IF($A12="", "", ROUND(B12*C12, 2)) | E12: =IF($A12="", "", $E$7) | F12: =IF($A12="", "", E12-D12) | G12: =IF($A12="", "", B12-F12) | H12: =IF($A12="", "", J11) | I12: =IF($A12="", "", ROUND(H12*C12, 2)) | J12: =IF($A12="", "", H12+I12) | K12: =IF($A12="", "", D12+I12) | L12: =IF($A12="", "", SUM(D13:$D$82)) | M12: =IF($A12="", "", G12+L12) | N12: =IF($A12="", "", M12+J12)
A13: =IF(ROW()-10<=$G$6, ROW()-10, "") | B13: =IF($A13="", "", G12) | C13: =IF($A13="", "", $C$8) | D13: =IF($A13="", "", ROUND(B13*C13, 2)) | E13: =IF($A13="", "", $E$7) | F13: =IF($A13="", "", E13-D13) | G13: =IF($A13="", "", B13-F13) | H13: =IF($A13="", "", J12) | I13: =IF($A13="", "", ROUND(H13*C13, 2)) | J13: =IF($A13="", "", H13+I13) | K13: =IF($A13="", "", D13+I13) | L13: =IF($A13="", "", SUM(D14:$D$82)) | M13: =IF($A13="", "", G13+L13) | N13: =IF($A13="", "", M13+J13)
A14: =IF(ROW()-10<=$G$6, ROW()-10, "") | B14: =IF($A14="", "", G13) | C14: =IF($A14="", "", $C$8) | D14: =IF($A14="", "", ROUND(B14*C14, 2)) | E14: =IF($A14="", "", $E$7) | F14: =IF($A14="", "", E14-D14) | G14: =IF($A14="", "", B14-F14) | H14: =IF($A14="", "", J13) | I14: =IF($A14="", "", ROUND(H14*C14, 2)) | J14: =IF($A14="", "", H14+I14) | K14: =IF($A14="", "", D14+I14) | L14: =IF($A14="", "", SUM(D15:$D$82)) | M14: =IF($A14="", "", G14+L14) | N14: =IF($A14="", "", M14+J14)
A15: =IF(ROW()-10<=$G$6, ROW()-10, "") | B15: =IF($A15="", "", G14) | C15: =IF($A15="", "", $C$8) | D15: =IF($A15="", "", ROUND(B15*C15, 2)) | E15: =IF($A15="", "", $E$7) | F15: =IF($A15="", "", E15-D15) | G15: =IF($A15="", "", B15-F15) | H15: =IF($A15="", "", J14) | I15: =IF($A15="", "", ROUND(H15*C15, 2)) | J15: =IF($A15="", "", H15+I15) | K15: =IF($A15="", "", D15+I15) | L15: =IF($A15="", "", SUM(D16:$D$82)) | M15: =IF($A15="", "", G15+L15) | N15: =IF($A15="", "", M15+J15)
A16: =IF(ROW()-10<=$G$6, ROW()-10, "") | B16: =IF($A16="", "", G15) | C16: =IF($A16="", "", $C$8) | D16: =IF($A16="", "", ROUND(B16*C16, 2)) | E16: =IF($A16="", "", $E$7) | F16: =IF($A16="", "", E16-D16) | G16: =IF($A16="", "", B16-F16) | H16: =IF($A16="", "", J15) | I16: =IF($A16="", "", ROUND(H16*C16, 2)) | J16: =IF($A16="", "", H16+I16) | K16: =IF($A16="", "", D16+I16) | L16: =IF($A16="", "", SUM(D17:$D$82)) | M16: =IF($A16="", "", G16+L16) | N16: =IF($A16="", "", M16+J16)
A17: =IF(ROW()-10<=$G$6, ROW()-10, "") | B17: =IF($A17="", "", G16) | C17: =IF($A17="", "", $C$8) | D17: =IF($A17="", "", ROUND(B17*C17, 2)) | E17: =IF($A17="", "", $E$7) | F17: =IF($A17="", "", E17-D17) | G17: =IF($A17="", "", B17-F17) | H17: =IF($A17="", "", J16) | I17: =IF($A17="", "", ROUND(H17*C17, 2)) | J17: =IF($A17="", "", H17+I17) | K17: =IF($A17="", "", D17+I17) | L17: =IF($A17="", "", SUM(D18:$D$82)) | M17: =IF($A17="", "", G17+L17) | N17: =IF($A17="", "", M17+J17)
A18: =IF(ROW()-10<=$G$6, ROW()-10, "") | B18: =IF($A18="", "", G17) | C18: =IF($A18="", "", $C$8) | D18: =IF($A18="", "", ROUND(B18*C18, 2)) | E18: =IF($A18="", "", $E$7) | F18: =IF($A18="", "", E18-D18) | G18: =IF($A18="", "", B18-F18) | H18: =IF($A18="", "", J17) | I18: =IF($A18="", "", ROUND(H18*C18, 2)) | J18: =IF($A18="", "", H18+I18) | K18: =IF($A18="", "", D18+I18) | L18: =IF($A18="", "", SUM(D19:$D$82)) | M18: =IF($A18="", "", G18+L18) | N18: =IF($A18="", "", M18+J18)
A19: =IF(ROW()-10<=$G$6, ROW()-10, "") | B19: =IF($A19="", "", G18) | C19: =IF($A19="", "", $C$8) | D19: =IF($A19="", "", ROUND(B19*C19, 2)) | E19: =IF($A19="", "", $E$7) | F19: =IF($A19="", "", E19-D19) | G19: =IF($A19="", "", B19-F19) | H19: =IF($A19="", "", J18) | I19: =IF($A19="", "", ROUND(H19*C19, 2)) | J19: =IF($A19="", "", H19+I19) | K19: =IF($A19="", "", D19+I19) | L19: =IF($A19="", "", SUM(D20:$D$82)) | M19: =IF($A19="", "", G19+L19) | N19: =IF($A19="", "", M19+J19)
A20: =IF(ROW()-10<=$G$6, ROW()-10, "") | B20: =IF($A20="", "", G19) | C20: =IF($A20="", "", $C$8) | D20: =IF($A20="", "", ROUND(B20*C20, 2)) | E20: =IF($A20="", "", $E$7) | F20: =IF($A20="", "", E20-D20) | G20: =IF($A20="", "", B20-F20) | H20: =IF($A20="", "", J19) | I20: =IF($A20="", "", ROUND(H20*C20, 2)) | J20: =IF($A20="", "", H20+I20) | K20: =IF($A20="", "", D20+I20) | L20: =IF($A20="", "", SUM(D21:$D$82)) | M20: =IF($A20="", "", G20+L20) | N20: =IF($A20="", "", M20+J20)
A21: =IF(ROW()-10<=$G$6, ROW()-10, "") | B21: =IF($A21="", "", G20) | C21: =IF($A21="", "", $C$8) | D21: =IF($A21="", "", ROUND(B21*C21, 2)) | E21: =IF($A21="", "", $E$7) | F21: =IF($A21="", "", E21-D21) | G21: =IF($A21="", "", B21-F21) | H21: =IF($A21="", "", J20) | I21: =IF($A21="", "", ROUND(H21*C21, 2)) | J21: =IF($A21="", "", H21+I21) | K21: =IF($A21="", "", D21+I21) | L21: =IF($A21="", "", SUM(D22:$D$82)) | M21: =IF($A21="", "", G21+L21) | N21: =IF($A21="", "", M21+J21)
A22: =IF(ROW()-10<=$G$6, ROW()-10, "") | B22: =IF($A22="", "", G21) | C22: =IF($A22="", "", $C$8) | D22: =IF($A22="", "", ROUND(B22*C22, 2)) | E22: =IF($A22="", "", $E$7) | F22: =IF($A22="", "", E22-D22) | G22: =IF($A22="", "", B22-F22) | H22: =IF($A22="", "", J21) | I22: =IF($A22="", "", ROUND(H22*C22, 2)) | J22: =IF($A22="", "", H22+I22) | K22: =IF($A22="", "", D22+I22) | L22: =IF($A22="", "", SUM(D23:$D$82)) | M22: =IF($A22="", "", G22+L22) | N22: =IF($A22="", "", M22+J22)
A23: =IF(ROW()-10<=$G$6, ROW()-10, "") | B23: =IF($A23="", "", G22) | C23: =IF($A23="", "", $C$8) | D23: =IF($A23="", "", ROUND(B23*C23, 2)) | E23: =IF($A23="", "", $E$7) | F23: =IF($A23="", "", E23-D23) | G23: =IF($A23="", "", B23-F23) | H23: =IF($A23="", "", J22) | I23: =IF($A23="", "", ROUND(H23*C23, 2)) | J23: =IF($A23="", "", H23+I23) | K23: =IF($A23="", "", D23+I23) | L23: =IF($A23="", "", SUM(D24:$D$82)) | M23: =IF($A23="", "", G23+L23) | N23: =IF($A23="", "", M23+J23)
... A81: =IF(ROW()-10<=$G$6, ROW()-10, "") | B81: =IF($A81="", "", G80) | C81: =IF($A81="", "", $C$8) | D81: =IF($A81="", "", ROUND(B81*C81, 2)) | E81: =IF($A81="", "", $E$7) | F81: =IF($A81="", "", E81-D81) | G81: =IF($A81="", "", B81-F81) | H81: =IF($A81="", "", J80) | I81: =IF($A81="", "", ROUND(H81*C81, 2)) | J81: =IF($A81="", "", H81+I81) | K81: =IF($A81="", "", D81+I81) | L81: =IF($A81="", "", SUM(D82:$D$82)) | M81: =IF($A81="", "", G81+L81) | N81: =IF($A81="", "", M81+J81)
A82: =IF(ROW()-10<=$G$6, ROW()-10, "") | B82: =IF($A82="", "", G81) | C82: =IF($A82="", "", $C$8) | D82: =IF($A82="", "", ROUND(B82*C82, 2)) | E82: =IF($A82="", "", $E$7) | F82: =IF($A82="", "", E82-D82) | G82: =IF($A82="", "", B82-F82) | H82: =IF($A82="", "", J81) | I82: =IF($A82="", "", ROUND(H82*C82, 2)) | J82: =IF($A82="", "", H82+I82) | K82: =IF($A82="", "", D82+I82) | L82: =IF($A82="", "", 0) | M82: =IF($A82="", "", G82+L82) | N82: =IF($A82="", "", M82+J82)
A83: TOTALES DEL CONTRATO | D83: =SUM(D11:D82) | E83: =SUM(E11:E82) | F83: =SUM(F11:F82) | I83: =SUM(I11:I82) | K83: =SUM(K11:K82)

Sheet Intereses_Leasing_Mensual
A1: O-LEASING · UNA APP DE ORANGE CREW · Intereses de Leasing Devengados Mes a Mes
A2: Devengo mensual de intereses de leasing con fórmulas vivas de saldo de capital por tasa · Auditoría Financiera NIF C-15 / IFRS 16 · Desarrollado por Orange Crew
A4: ID_Contrato | B4: Cliente | C4: Vehiculo | D4: Estatus | E4: Fecha_Alta | F4: Fecha_Vencimiento | G4: Plazo | H4: Inversion_Neta | I4: 2026-01 | J4: 2026-02 | K4: 2026-03 | L4: 2026-04 | M4: 2026-05 | N4: 2026-06 | O4: 2026-07 | P4: 2026-08 | Q4: 2026-09 | R4: 2026-10 | S4: 2026-11 | T4: 2026-12 | U4: Total_Devengado_Leasing
A5: 0326-0003 | B5: Alberto Vázquez Solorio | C5: Volkswagen Tiguan R-Line 2026 | D5: ACTIVO | E5: 2026-09-16 | F5: 2030-09-16 | G5: 48 | H5: 406120.26 | Q5: =ROUND('Resumen_Cartera'!$K5 * 'Resumen_Cartera'!$Q5, 2) | R5: =IF(Saldos_Capital_Mensual!Q5>0, ROUND(Saldos_Capital_Mensual!Q5 * 'Resumen_Cartera'!$Q5, 2), "") | S5: =IF(Saldos_Capital_Mensual!R5>0, ROUND(Saldos_Capital_Mensual!R5 * 'Resumen_Cartera'!$Q5, 2), "") | T5: =IF(Saldos_Capital_Mensual!S5>0, ROUND(Saldos_Capital_Mensual!S5 * 'Resumen_Cartera'!$Q5, 2), "") | U5: =SUM(I5:T5)
A6: 0472-0003 | B6: Miguel Zazueta Beltrán | C6: Jeep Grand Cherokee | D6: ACTIVO | E6: 2026-02-03 | F6: 2029-02-03 | G6: 36 | H6: 852203.53 | J6: =ROUND('Resumen_Cartera'!$K6 * 'Resumen_Cartera'!$Q6, 2) | K6: =IF(Saldos_Capital_Mensual!J6>0, ROUND(Saldos_Capital_Mensual!J6 * 'Resumen_Cartera'!$Q6, 2), "") | L6: =IF(Saldos_Capital_Mensual!K6>0, ROUND(Saldos_Capital_Mensual!K6 * 'Resumen_Cartera'!$Q6, 2), "") | M6: =IF(Saldos_Capital_Mensual!L6>0, ROUND(Saldos_Capital_Mensual!L6 * 'Resumen_Cartera'!$Q6, 2), "") | N6: =IF(Saldos_Capital_Mensual!M6>0, ROUND(Saldos_Capital_Mensual!M6 * 'Resumen_Cartera'!$Q6, 2), "") | O6: =IF(Saldos_Capital_Mensual!N6>0, ROUND(Saldos_Capital_Mensual!N6 * 'Resumen_Cartera'!$Q6, 2), "") | P6: =IF(Saldos_Capital_Mensual!O6>0, ROUND(Saldos_Capital_Mensual!O6 * 'Resumen_Cartera'!$Q6, 2), "") | Q6: =IF(Saldos_Capital_Mensual!P6>0, ROUND(Saldos_Capital_Mensual!P6 * 'Resumen_Cartera'!$Q6, 2), "") | R6: =IF(Saldos_Capital_Mensual!Q6>0, ROUND(Saldos_Capital_Mensual!Q6 * 'Resumen_Cartera'!$Q6, 2), "") | ... T6: =IF(Saldos_Capital_Mensual!S6>0, ROUND(Saldos_Capital_Mensual!S6 * 'Resumen_Cartera'!$Q6, 2), "") | U6: =SUM(I6:T6)
A7: 0504-0004 | B7: Oscar Ivan Lozano Terriquez | C7: 700 BIGHORN "S" CREW CAB MT | D7: ACTIVO | E7: 2026-01-05 | F7: 2027-01-05 | G7: 12 | H7: 229125 | I7: =ROUND('Resumen_Cartera'!$K7 * 'Resumen_Cartera'!$Q7, 2) | J7: =IF(Saldos_Capital_Mensual!I7>0, ROUND(Saldos_Capital_Mensual!I7 * 'Resumen_Cartera'!$Q7, 2), "") | K7: =IF(Saldos_Capital_Mensual!J7>0, ROUND(Saldos_Capital_Mensual!J7 * 'Resumen_Cartera'!$Q7, 2), "") | L7: =IF(Saldos_Capital_Mensual!K7>0, ROUND(Saldos_Capital_Mensual!K7 * 'Resumen_Cartera'!$Q7, 2), "") | M7: =IF(Saldos_Capital_Mensual!L7>0, ROUND(Saldos_Capital_Mensual!L7 * 'Resumen_Cartera'!$Q7, 2), "") | N7: =IF(Saldos_Capital_Mensual!M7>0, ROUND(Saldos_Capital_Mensual!M7 * 'Resumen_Cartera'!$Q7, 2), "") | O7: =IF(Saldos_Capital_Mensual!N7>0, ROUND(Saldos_Capital_Mensual!N7 * 'Resumen_Cartera'!$Q7, 2), "") | P7: =IF(Saldos_Capital_Mensual!O7>0, ROUND(Saldos_Capital_Mensual!O7 * 'Resumen_Cartera'!$Q7, 2), "") | Q7: =IF(Saldos_Capital_Mensual!P7>0, ROUND(Saldos_Capital_Mensual!P7 * 'Resumen_Cartera'!$Q7, 2), "") | ... T7: =IF(Saldos_Capital_Mensual!S7>0, ROUND(Saldos_Capital_Mensual!S7 * 'Resumen_Cartera'!$Q7, 2), "") | U7: =SUM(I7:T7)
A8: 0506-0006 | B8: Electronic Accounting Sa de Cv | C8: X5 | D8: ACTIVO | E8: 2024-01-10 | F8: 2027-01-10 | G8: 36 | H8: 1336969.4 | I8: =ROUND(868919.79 * 'Resumen_Cartera'!$Q8, 2) | J8: =IF(Saldos_Capital_Mensual!I8>0, ROUND(Saldos_Capital_Mensual!I8 * 'Resumen_Cartera'!$Q8, 2), "") | K8: =IF(Saldos_Capital_Mensual!J8>0, ROUND(Saldos_Capital_Mensual!J8 * 'Resumen_Cartera'!$Q8, 2), "") | L8: =IF(Saldos_Capital_Mensual!K8>0, ROUND(Saldos_Capital_Mensual!K8 * 'Resumen_Cartera'!$Q8, 2), "") | M8: =IF(Saldos_Capital_Mensual!L8>0, ROUND(Saldos_Capital_Mensual!L8 * 'Resumen_Cartera'!$Q8, 2), "") | N8: =IF(Saldos_Capital_Mensual!M8>0, ROUND(Saldos_Capital_Mensual!M8 * 'Resumen_Cartera'!$Q8, 2), "") | O8: =IF(Saldos_Capital_Mensual!N8>0, ROUND(Saldos_Capital_Mensual!N8 * 'Resumen_Cartera'!$Q8, 2), "") | P8: =IF(Saldos_Capital_Mensual!O8>0, ROUND(Saldos_Capital_Mensual!O8 * 'Resumen_Cartera'!$Q8, 2), "") | Q8: =IF(Saldos_Capital_Mensual!P8>0, ROUND(Saldos_Capital_Mensual!P8 * 'Resumen_Cartera'!$Q8, 2), "") | ... T8: =IF(Saldos_Capital_Mensual!S8>0, ROUND(Saldos_Capital_Mensual!S8 * 'Resumen_Cartera'!$Q8, 2), "") | U8: =SUM(I8:T8)
A9: 0506-0007 | B9: Electronic Acounting | C9: L200 Glx Diesel | D9: ACTIVO | E9: 2024-09-05 | F9: 2027-09-05 | G9: 36 | H9: 536762.93 | I9: =ROUND(409096.92 * 'Resumen_Cartera'!$Q9, 2) | J9: =IF(Saldos_Capital_Mensual!I9>0, ROUND(Saldos_Capital_Mensual!I9 * 'Resumen_Cartera'!$Q9, 2), "") | K9: =IF(Saldos_Capital_Mensual!J9>0, ROUND(Saldos_Capital_Mensual!J9 * 'Resumen_Cartera'!$Q9, 2), "") | L9: =IF(Saldos_Capital_Mensual!K9>0, ROUND(Saldos_Capital_Mensual!K9 * 'Resumen_Cartera'!$Q9, 2), "") | M9: =IF(Saldos_Capital_Mensual!L9>0, ROUND(Saldos_Capital_Mensual!L9 * 'Resumen_Cartera'!$Q9, 2), "") | N9: =IF(Saldos_Capital_Mensual!M9>0, ROUND(Saldos_Capital_Mensual!M9 * 'Resumen_Cartera'!$Q9, 2), "") | O9: =IF(Saldos_Capital_Mensual!N9>0, ROUND(Saldos_Capital_Mensual!N9 * 'Resumen_Cartera'!$Q9, 2), "") | P9: =IF(Saldos_Capital_Mensual!O9>0, ROUND(Saldos_Capital_Mensual!O9 * 'Resumen_Cartera'!$Q9, 2), "") | Q9: =IF(Saldos_Capital_Mensual!P9>0, ROUND(Saldos_Capital_Mensual!P9 * 'Resumen_Cartera'!$Q9, 2), "") | ... T9: =IF(Saldos_Capital_Mensual!S9>0, ROUND(Saldos_Capital_Mensual!S9 * 'Resumen_Cartera'!$Q9, 2), "") | U9: =SUM(I9:T9)
A10: 0519-0005 | B10: Tequilas el Mexicano S.A. de C.V. | C10: Attitude Sport | D10: ACTIVO | E10: 2025-07-14 | F10: 2029-07-14 | G10: 48 | H10: 317250 | I10: =ROUND(298355.25 * 'Resumen_Cartera'!$Q10, 2) | J10: =IF(Saldos_Capital_Mensual!I10>0, ROUND(Saldos_Capital_Mensual!I10 * 'Resumen_Cartera'!$Q10, 2), "") | K10: =IF(Saldos_Capital_Mensual!J10>0, ROUND(Saldos_Capital_Mensual!J10 * 'Resumen_Cartera'!$Q10, 2), "") | L10: =IF(Saldos_Capital_Mensual!K10>0, ROUND(Saldos_Capital_Mensual!K10 * 'Resumen_Cartera'!$Q10, 2), "") | M10: =IF(Saldos_Capital_Mensual!L10>0, ROUND(Saldos_Capital_Mensual!L10 * 'Resumen_Cartera'!$Q10, 2), "") | N10: =IF(Saldos_Capital_Mensual!M10>0, ROUND(Saldos_Capital_Mensual!M10 * 'Resumen_Cartera'!$Q10, 2), "") | O10: =IF(Saldos_Capital_Mensual!N10>0, ROUND(Saldos_Capital_Mensual!N10 * 'Resumen_Cartera'!$Q10, 2), "") | P10: =IF(Saldos_Capital_Mensual!O10>0, ROUND(Saldos_Capital_Mensual!O10 * 'Resumen_Cartera'!$Q10, 2), "") | Q10: =IF(Saldos_Capital_Mensual!P10>0, ROUND(Saldos_Capital_Mensual!P10 * 'Resumen_Cartera'!$Q10, 2), "") | ... T10: =IF(Saldos_Capital_Mensual!S10>0, ROUND(Saldos_Capital_Mensual!S10 * 'Resumen_Cartera'!$Q10, 2), "") | U10: =SUM(I10:T10)
A11: 0520-0003 | B11: Tractomotriz Diesel Leal, S.A. de C.V. | C11: Montero Sport | D11: ACTIVO | E11: 2025-11-28 | F11: 2028-11-28 | G11: 36 | H11: 372879.31 | I11: =ROUND(362238.02 * 'Resumen_Cartera'!$Q11, 2) | J11: =IF(Saldos_Capital_Mensual!I11>0, ROUND(Saldos_Capital_Mensual!I11 * 'Resumen_Cartera'!$Q11, 2), "") | K11: =IF(Saldos_Capital_Mensual!J11>0, ROUND(Saldos_Capital_Mensual!J11 * 'Resumen_Cartera'!$Q11, 2), "") | L11: =IF(Saldos_Capital_Mensual!K11>0, ROUND(Saldos_Capital_Mensual!K11 * 'Resumen_Cartera'!$Q11, 2), "") | M11: =IF(Saldos_Capital_Mensual!L11>0, ROUND(Saldos_Capital_Mensual!L11 * 'Resumen_Cartera'!$Q11, 2), "") | N11: =IF(Saldos_Capital_Mensual!M11>0, ROUND(Saldos_Capital_Mensual!M11 * 'Resumen_Cartera'!$Q11, 2), "") | O11: =IF(Saldos_Capital_Mensual!N11>0, ROUND(Saldos_Capital_Mensual!N11 * 'Resumen_Cartera'!$Q11, 2), "") | P11: =IF(Saldos_Capital_Mensual!O11>0, ROUND(Saldos_Capital_Mensual!O11 * 'Resumen_Cartera'!$Q11, 2), "") | Q11: =IF(Saldos_Capital_Mensual!P11>0, ROUND(Saldos_Capital_Mensual!P11 * 'Resumen_Cartera'!$Q11, 2), "") | ... T11: =IF(Saldos_Capital_Mensual!S11>0, ROUND(Saldos_Capital_Mensual!S11 * 'Resumen_Cartera'!$Q11, 2), "") | U11: =SUM(I11:T11)
A12: 0520-0004 | B12: Tractomotriz Diesel Leal, S.A. de C.V. | C12: Partner Maxi Pack | D12: ACTIVO | E12: 2025-12-04 | F12: 2028-12-04 | G12: 36 | H12: 240218.27 | I12: =ROUND(236835.63 * 'Resumen_Cartera'!$Q12, 2) | J12: =IF(Saldos_Capital_Mensual!I12>0, ROUND(Saldos_Capital_Mensual!I12 * 'Resumen_Cartera'!$Q12, 2), "") | K12: =IF(Saldos_Capital_Mensual!J12>0, ROUND(Saldos_Capital_Mensual!J12 * 'Resumen_Cartera'!$Q12, 2), "") | L12: =IF(Saldos_Capital_Mensual!K12>0, ROUND(Saldos_Capital_Mensual!K12 * 'Resumen_Cartera'!$Q12, 2), "") | M12: =IF(Saldos_Capital_Mensual!L12>0, ROUND(Saldos_Capital_Mensual!L12 * 'Resumen_Cartera'!$Q12, 2), "") | N12: =IF(Saldos_Capital_Mensual!M12>0, ROUND(Saldos_Capital_Mensual!M12 * 'Resumen_Cartera'!$Q12, 2), "") | O12: =IF(Saldos_Capital_Mensual!N12>0, ROUND(Saldos_Capital_Mensual!N12 * 'Resumen_Cartera'!$Q12, 2), "") | P12: =IF(Saldos_Capital_Mensual!O12>0, ROUND(Saldos_Capital_Mensual!O12 * 'Resumen_Cartera'!$Q12, 2), "") | Q12: =IF(Saldos_Capital_Mensual!P12>0, ROUND(Saldos_Capital_Mensual!P12 * 'Resumen_Cartera'!$Q12, 2), "") | ... T12: =IF(Saldos_Capital_Mensual!S12>0, ROUND(Saldos_Capital_Mensual!S12 * 'Resumen_Cartera'!$Q12, 2), "") | U12: =SUM(I12:T12)
A13: 0521-0002 | B13: Carlos Hiram leal Leal | C13: Xpander | D13: ACTIVO | E13: 2025-09-08 | F13: 2028-09-08 | G13: 36 | H13: 329389.91 | I13: =ROUND(311366.72 * 'Resumen_Cartera'!$Q13, 2) | J13: =IF(Saldos_Capital_Mensual!I13>0, ROUND(Saldos_Capital_Mensual!I13 * 'Resumen_Cartera'!$Q13, 2), "") | K13: =IF(Saldos_Capital_Mensual!J13>0, ROUND(Saldos_Capital_Mensual!J13 * 'Resumen_Cartera'!$Q13, 2), "") | L13: =IF(Saldos_Capital_Mensual!K13>0, ROUND(Saldos_Capital_Mensual!K13 * 'Resumen_Cartera'!$Q13, 2), "") | M13: =IF(Saldos_Capital_Mensual!L13>0, ROUND(Saldos_Capital_Mensual!L13 * 'Resumen_Cartera'!$Q13, 2), "") | N13: =IF(Saldos_Capital_Mensual!M13>0, ROUND(Saldos_Capital_Mensual!M13 * 'Resumen_Cartera'!$Q13, 2), "") | O13: =IF(Saldos_Capital_Mensual!N13>0, ROUND(Saldos_Capital_Mensual!N13 * 'Resumen_Cartera'!$Q13, 2), "") | P13: =IF(Saldos_Capital_Mensual!O13>0, ROUND(Saldos_Capital_Mensual!O13 * 'Resumen_Cartera'!$Q13, 2), "") | Q13: =IF(Saldos_Capital_Mensual!P13>0, ROUND(Saldos_Capital_Mensual!P13 * 'Resumen_Cartera'!$Q13, 2), "") | ... T13: =IF(Saldos_Capital_Mensual!S13>0, ROUND(Saldos_Capital_Mensual!S13 * 'Resumen_Cartera'!$Q13, 2), "") | U13: =SUM(I13:T13)
A14: 0524-0007 | B14: Lider En Derecho De Via y Construcción SA DE CV | C14: L200 Gls | D14: ACTIVO | E14: 2025-08-15 | F14: 2027-08-15 | G14: 24 | H14: 584988.36 | I14: =ROUND(522407.52 * 'Resumen_Cartera'!$Q14, 2) | J14: =IF(Saldos_Capital_Mensual!I14>0, ROUND(Saldos_Capital_Mensual!I14 * 'Resumen_Cartera'!$Q14, 2), "") | K14: =IF(Saldos_Capital_Mensual!J14>0, ROUND(Saldos_Capital_Mensual!J14 * 'Resumen_Cartera'!$Q14, 2), "") | L14: =IF(Saldos_Capital_Mensual!K14>0, ROUND(Saldos_Capital_Mensual!K14 * 'Resumen_Cartera'!$Q14, 2), "") | M14: =IF(Saldos_Capital_Mensual!L14>0, ROUND(Saldos_Capital_Mensual!L14 * 'Resumen_Cartera'!$Q14, 2), "") | N14: =IF(Saldos_Capital_Mensual!M14>0, ROUND(Saldos_Capital_Mensual!M14 * 'Resumen_Cartera'!$Q14, 2), "") | O14: =IF(Saldos_Capital_Mensual!N14>0, ROUND(Saldos_Capital_Mensual!N14 * 'Resumen_Cartera'!$Q14, 2), "") | P14: =IF(Saldos_Capital_Mensual!O14>0, ROUND(Saldos_Capital_Mensual!O14 * 'Resumen_Cartera'!$Q14, 2), "") | Q14: =IF(Saldos_Capital_Mensual!P14>0, ROUND(Saldos_Capital_Mensual!P14 * 'Resumen_Cartera'!$Q14, 2), "") | ... T14: =IF(Saldos_Capital_Mensual!S14>0, ROUND(Saldos_Capital_Mensual!S14 * 'Resumen_Cartera'!$Q14, 2), "") | U14: =SUM(I14:T14)
A15: 0524-0011 | B15: Lider En Derecho De Via y Construcción SA DE CV | C15: Wrangler Unlimited Sahara | D15: ACTIVO | E15: 2025-12-31 | F15: 2029-12-31 | G15: 48 | H15: 846843.45 | I15: =ROUND(839101.7 * 'Resumen_Cartera'!$Q15, 2) | J15: =IF(Saldos_Capital_Mensual!I15>0, ROUND(Saldos_Capital_Mensual!I15 * 'Resumen_Cartera'!$Q15, 2), "") | K15: =IF(Saldos_Capital_Mensual!J15>0, ROUND(Saldos_Capital_Mensual!J15 * 'Resumen_Cartera'!$Q15, 2), "") | L15: =IF(Saldos_Capital_Mensual!K15>0, ROUND(Saldos_Capital_Mensual!K15 * 'Resumen_Cartera'!$Q15, 2), "") | M15: =IF(Saldos_Capital_Mensual!L15>0, ROUND(Saldos_Capital_Mensual!L15 * 'Resumen_Cartera'!$Q15, 2), "") | N15: =IF(Saldos_Capital_Mensual!M15>0, ROUND(Saldos_Capital_Mensual!M15 * 'Resumen_Cartera'!$Q15, 2), "") | O15: =IF(Saldos_Capital_Mensual!N15>0, ROUND(Saldos_Capital_Mensual!N15 * 'Resumen_Cartera'!$Q15, 2), "") | P15: =IF(Saldos_Capital_Mensual!O15>0, ROUND(Saldos_Capital_Mensual!O15 * 'Resumen_Cartera'!$Q15, 2), "") | Q15: =IF(Saldos_Capital_Mensual!P15>0, ROUND(Saldos_Capital_Mensual!P15 * 'Resumen_Cartera'!$Q15, 2), "") | ... T15: =IF(Saldos_Capital_Mensual!S15>0, ROUND(Saldos_Capital_Mensual!S15 * 'Resumen_Cartera'!$Q15, 2), "") | U15: =SUM(I15:T15)
A16: 0524-0012 | B16: Lider En Derecho De Via y Construcción SA DE CV | C16: L200 GLS | D16: ACTIVO | E16: 2026-03-17 | F16: 2030-03-17 | G16: 48 | H16: 561738.88 | K16: =ROUND('Resumen_Cartera'!$K16 * 'Resumen_Cartera'!$Q16, 2) | L16: =IF(Saldos_Capital_Mensual!K16>0, ROUND(Saldos_Capital_Mensual!K16 * 'Resumen_Cartera'!$Q16, 2), "") | M16: =IF(Saldos_Capital_Mensual!L16>0, ROUND(Saldos_Capital_Mensual!L16 * 'Resumen_Cartera'!$Q16, 2), "") | N16: =IF(Saldos_Capital_Mensual!M16>0, ROUND(Saldos_Capital_Mensual!M16 * 'Resumen_Cartera'!$Q16, 2), "") | O16: =IF(Saldos_Capital_Mensual!N16>0, ROUND(Saldos_Capital_Mensual!N16 * 'Resumen_Cartera'!$Q16, 2), "") | P16: =IF(Saldos_Capital_Mensual!O16>0, ROUND(Saldos_Capital_Mensual!O16 * 'Resumen_Cartera'!$Q16, 2), "") | Q16: =IF(Saldos_Capital_Mensual!P16>0, ROUND(Saldos_Capital_Mensual!P16 * 'Resumen_Cartera'!$Q16, 2), "") | R16: =IF(Saldos_Capital_Mensual!Q16>0, ROUND(Saldos_Capital_Mensual!Q16 * 'Resumen_Cartera'!$Q16, 2), "") | S16: =IF(Saldos_Capital_Mensual!R16>0, ROUND(Saldos_Capital_Mensual!R16 * 'Resumen_Cartera'!$Q16, 2), "") | T16: =IF(Saldos_Capital_Mensual!S16>0, ROUND(Saldos_Capital_Mensual!S16 * 'Resumen_Cartera'!$Q16, 2), "") | U16: =SUM(I16:T16)
A17: 0524-0013 | B17: Lider En Derecho De Via y Construcción SA DE CV | C17: L200 GLX | D17: ACTIVO | E17: 2026-06-23 | F17: 2029-06-23 | G17: 36 | H17: 597925 | N17: =ROUND('Resumen_Cartera'!$K17 * 'Resumen_Cartera'!$Q17, 2) | O17: =IF(Saldos_Capital_Mensual!N17>0, ROUND(Saldos_Capital_Mensual!N17 * 'Resumen_Cartera'!$Q17, 2), "") | P17: =IF(Saldos_Capital_Mensual!O17>0, ROUND(Saldos_Capital_Mensual!O17 * 'Resumen_Cartera'!$Q17, 2), "") | Q17: =IF(Saldos_Capital_Mensual!P17>0, ROUND(Saldos_Capital_Mensual!P17 * 'Resumen_Cartera'!$Q17, 2), "") | R17: =IF(Saldos_Capital_Mensual!Q17>0, ROUND(Saldos_Capital_Mensual!Q17 * 'Resumen_Cartera'!$Q17, 2), "") | S17: =IF(Saldos_Capital_Mensual!R17>0, ROUND(Saldos_Capital_Mensual!R17 * 'Resumen_Cartera'!$Q17, 2), "") | T17: =IF(Saldos_Capital_Mensual!S17>0, ROUND(Saldos_Capital_Mensual!S17 * 'Resumen_Cartera'!$Q17, 2), "") | U17: =SUM(I17:T17)
A18: 0524-0014 | B18: Lider En Derecho De Via y Construcción SA DE CV | C18: L200 GLX | D18: ACTIVO | E18: 2026-06-23 | F18: 2029-06-23 | G18: 36 | H18: 597925 | N18: =ROUND('Resumen_Cartera'!$K18 * 'Resumen_Cartera'!$Q18, 2) | O18: =IF(Saldos_Capital_Mensual!N18>0, ROUND(Saldos_Capital_Mensual!N18 * 'Resumen_Cartera'!$Q18, 2), "") | P18: =IF(Saldos_Capital_Mensual!O18>0, ROUND(Saldos_Capital_Mensual!O18 * 'Resumen_Cartera'!$Q18, 2), "") | Q18: =IF(Saldos_Capital_Mensual!P18>0, ROUND(Saldos_Capital_Mensual!P18 * 'Resumen_Cartera'!$Q18, 2), "") | R18: =IF(Saldos_Capital_Mensual!Q18>0, ROUND(Saldos_Capital_Mensual!Q18 * 'Resumen_Cartera'!$Q18, 2), "") | S18: =IF(Saldos_Capital_Mensual!R18>0, ROUND(Saldos_Capital_Mensual!R18 * 'Resumen_Cartera'!$Q18, 2), "") | T18: =IF(Saldos_Capital_Mensual!S18>0, ROUND(Saldos_Capital_Mensual!S18 * 'Resumen_Cartera'!$Q18, 2), "") | U18: =SUM(I18:T18)
A19: 0524-0015 | B19: Lider En Derecho De Via y Construcción SA DE CV | C19: Mitsubishi L200 GLX 2026 | D19: ACTIVO | E19: 2026-07-29 | F19: 2029-07-29 | G19: 36 | H19: 515452.59 | O19: =ROUND('Resumen_Cartera'!$K19 * 'Resumen_Cartera'!$Q19, 2) | P19: =IF(Saldos_Capital_Mensual!O19>0, ROUND(Saldos_Capital_Mensual!O19 * 'Resumen_Cartera'!$Q19, 2), "") | Q19: =IF(Saldos_Capital_Mensual!P19>0, ROUND(Saldos_Capital_Mensual!P19 * 'Resumen_Cartera'!$Q19, 2), "") | R19: =IF(Saldos_Capital_Mensual!Q19>0, ROUND(Saldos_Capital_Mensual!Q19 * 'Resumen_Cartera'!$Q19, 2), "") | S19: =IF(Saldos_Capital_Mensual!R19>0, ROUND(Saldos_Capital_Mensual!R19 * 'Resumen_Cartera'!$Q19, 2), "") | T19: =IF(Saldos_Capital_Mensual!S19>0, ROUND(Saldos_Capital_Mensual!S19 * 'Resumen_Cartera'!$Q19, 2), "") | U19: =SUM(I19:T19)
A20: 0524-0016 | B20: Lider En Derecho De Via y Construcción SA DE CV | C20: Mitsubishi L200 GLX 2026 | D20: ACTIVO | E20: 2026-07-29 | F20: 2029-07-29 | G20: 36 | H20: 515452.59 | O20: =ROUND('Resumen_Cartera'!$K20 * 'Resumen_Cartera'!$Q20, 2) | P20: =IF(Saldos_Capital_Mensual!O20>0, ROUND(Saldos_Capital_Mensual!O20 * 'Resumen_Cartera'!$Q20, 2), "") | Q20: =IF(Saldos_Capital_Mensual!P20>0, ROUND(Saldos_Capital_Mensual!P20 * 'Resumen_Cartera'!$Q20, 2), "") | R20: =IF(Saldos_Capital_Mensual!Q20>0, ROUND(Saldos_Capital_Mensual!Q20 * 'Resumen_Cartera'!$Q20, 2), "") | S20: =IF(Saldos_Capital_Mensual!R20>0, ROUND(Saldos_Capital_Mensual!R20 * 'Resumen_Cartera'!$Q20, 2), "") | T20: =IF(Saldos_Capital_Mensual!S20>0, ROUND(Saldos_Capital_Mensual!S20 * 'Resumen_Cartera'!$Q20, 2), "") | U20: =SUM(I20:T20)
A21: 0527-0003 | B21: Comercilizadora e Importadora Nabega Sa de Cv | C21: RAM 700 Big Horn CVT | D21: ACTIVO | E21: 2024-05-30 | F21: 2027-05-30 | G21: 36 | H21: 289586.21 | I21: =ROUND(221927.38 * 'Resumen_Cartera'!$Q21, 2) | J21: =IF(Saldos_Capital_Mensual!I21>0, ROUND(Saldos_Capital_Mensual!I21 * 'Resumen_Cartera'!$Q21, 2), "") | K21: =IF(Saldos_Capital_Mensual!J21>0, ROUND(Saldos_Capital_Mensual!J21 * 'Resumen_Cartera'!$Q21, 2), "") | L21: =IF(Saldos_Capital_Mensual!K21>0, ROUND(Saldos_Capital_Mensual!K21 * 'Resumen_Cartera'!$Q21, 2), "") | M21: =IF(Saldos_Capital_Mensual!L21>0, ROUND(Saldos_Capital_Mensual!L21 * 'Resumen_Cartera'!$Q21, 2), "") | N21: =IF(Saldos_Capital_Mensual!M21>0, ROUND(Saldos_Capital_Mensual!M21 * 'Resumen_Cartera'!$Q21, 2), "") | O21: =IF(Saldos_Capital_Mensual!N21>0, ROUND(Saldos_Capital_Mensual!N21 * 'Resumen_Cartera'!$Q21, 2), "") | P21: =IF(Saldos_Capital_Mensual!O21>0, ROUND(Saldos_Capital_Mensual!O21 * 'Resumen_Cartera'!$Q21, 2), "") | Q21: =IF(Saldos_Capital_Mensual!P21>0, ROUND(Saldos_Capital_Mensual!P21 * 'Resumen_Cartera'!$Q21, 2), "") | ... T21: =IF(Saldos_Capital_Mensual!S21>0, ROUND(Saldos_Capital_Mensual!S21 * 'Resumen_Cartera'!$Q21, 2), "") | U21: =SUM(I21:T21)
A22: 0527-0004 | B22: Comercilizadora e Importadora Nabega Sa de Cv | C22: Gmc Denali | D22: ACTIVO | E22: 2025-07-31 | F22: 2029-07-31 | G22: 48 | H22: 991086.21 | I22: =ROUND(939512.73 * 'Resumen_Cartera'!$Q22, 2) | J22: =IF(Saldos_Capital_Mensual!I22>0, ROUND(Saldos_Capital_Mensual!I22 * 'Resumen_Cartera'!$Q22, 2), "") | K22: =IF(Saldos_Capital_Mensual!J22>0, ROUND(Saldos_Capital_Mensual!J22 * 'Resumen_Cartera'!$Q22, 2), "") | L22: =IF(Saldos_Capital_Mensual!K22>0, ROUND(Saldos_Capital_Mensual!K22 * 'Resumen_Cartera'!$Q22, 2), "") | M22: =IF(Saldos_Capital_Mensual!L22>0, ROUND(Saldos_Capital_Mensual!L22 * 'Resumen_Cartera'!$Q22, 2), "") | N22: =IF(Saldos_Capital_Mensual!M22>0, ROUND(Saldos_Capital_Mensual!M22 * 'Resumen_Cartera'!$Q22, 2), "") | O22: =IF(Saldos_Capital_Mensual!N22>0, ROUND(Saldos_Capital_Mensual!N22 * 'Resumen_Cartera'!$Q22, 2), "") | P22: =IF(Saldos_Capital_Mensual!O22>0, ROUND(Saldos_Capital_Mensual!O22 * 'Resumen_Cartera'!$Q22, 2), "") | Q22: =IF(Saldos_Capital_Mensual!P22>0, ROUND(Saldos_Capital_Mensual!P22 * 'Resumen_Cartera'!$Q22, 2), "") | ... T22: =IF(Saldos_Capital_Mensual!S22>0, ROUND(Saldos_Capital_Mensual!S22 * 'Resumen_Cartera'!$Q22, 2), "") | U22: =SUM(I22:T22)
A23: 0527-0005 | B23: Comercilizadora e Importadora Nabega Sa de Cv | C23: Gle 450 Sport | D23: ACTIVO | E23: 2025-08-16 | F23: 2028-08-16 | G23: 36 | H23: 1050525 | I23: =ROUND(981905.12 * 'Resumen_Cartera'!$Q23, 2) | J23: =IF(Saldos_Capital_Mensual!I23>0, ROUND(Saldos_Capital_Mensual!I23 * 'Resumen_Cartera'!$Q23, 2), "") | K23: =IF(Saldos_Capital_Mensual!J23>0, ROUND(Saldos_Capital_Mensual!J23 * 'Resumen_Cartera'!$Q23, 2), "") | L23: =IF(Saldos_Capital_Mensual!K23>0, ROUND(Saldos_Capital_Mensual!K23 * 'Resumen_Cartera'!$Q23, 2), "") | M23: =IF(Saldos_Capital_Mensual!L23>0, ROUND(Saldos_Capital_Mensual!L23 * 'Resumen_Cartera'!$Q23, 2), "") | N23: =IF(Saldos_Capital_Mensual!M23>0, ROUND(Saldos_Capital_Mensual!M23 * 'Resumen_Cartera'!$Q23, 2), "") | O23: =IF(Saldos_Capital_Mensual!N23>0, ROUND(Saldos_Capital_Mensual!N23 * 'Resumen_Cartera'!$Q23, 2), "") | P23: =IF(Saldos_Capital_Mensual!O23>0, ROUND(Saldos_Capital_Mensual!O23 * 'Resumen_Cartera'!$Q23, 2), "") | Q23: =IF(Saldos_Capital_Mensual!P23>0, ROUND(Saldos_Capital_Mensual!P23 * 'Resumen_Cartera'!$Q23, 2), "") | ... T23: =IF(Saldos_Capital_Mensual!S23>0, ROUND(Saldos_Capital_Mensual!S23 * 'Resumen_Cartera'!$Q23, 2), "") | U23: =SUM(I23:T23)
A24: 0531-0002 | B24: Otcada Mex, S. de R.L. de C.V. | C24: Grand Cherokee Limited | D24: ACTIVO | E24: 2026-06-18 | F24: 2030-06-18 | G24: 48 | H24: 779340 | N24: =ROUND('Resumen_Cartera'!$K24 * 'Resumen_Cartera'!$Q24, 2) | O24: =IF(Saldos_Capital_Mensual!N24>0, ROUND(Saldos_Capital_Mensual!N24 * 'Resumen_Cartera'!$Q24, 2), "") | P24: =IF(Saldos_Capital_Mensual!O24>0, ROUND(Saldos_Capital_Mensual!O24 * 'Resumen_Cartera'!$Q24, 2), "") | Q24: =IF(Saldos_Capital_Mensual!P24>0, ROUND(Saldos_Capital_Mensual!P24 * 'Resumen_Cartera'!$Q24, 2), "") | R24: =IF(Saldos_Capital_Mensual!Q24>0, ROUND(Saldos_Capital_Mensual!Q24 * 'Resumen_Cartera'!$Q24, 2), "") | S24: =IF(Saldos_Capital_Mensual!R24>0, ROUND(Saldos_Capital_Mensual!R24 * 'Resumen_Cartera'!$Q24, 2), "") | T24: =IF(Saldos_Capital_Mensual!S24>0, ROUND(Saldos_Capital_Mensual!S24 * 'Resumen_Cartera'!$Q24, 2), "") | U24: =SUM(I24:T24)
A25: 0546-0007 | B25: Norma Elena Bonilla Lupio | C25: GLC 350 E 4MATIC | D25: ACTIVO | E25: 2025-10-14 | F25: 2027-10-14 | G25: 24 | H25: 866917.24 | I25: =ROUND(797841.04 * 'Resumen_Cartera'!$Q25, 2) | J25: =IF(Saldos_Capital_Mensual!I25>0, ROUND(Saldos_Capital_Mensual!I25 * 'Resumen_Cartera'!$Q25, 2), "") | K25: =IF(Saldos_Capital_Mensual!J25>0, ROUND(Saldos_Capital_Mensual!J25 * 'Resumen_Cartera'!$Q25, 2), "") | L25: =IF(Saldos_Capital_Mensual!K25>0, ROUND(Saldos_Capital_Mensual!K25 * 'Resumen_Cartera'!$Q25, 2), "") | M25: =IF(Saldos_Capital_Mensual!L25>0, ROUND(Saldos_Capital_Mensual!L25 * 'Resumen_Cartera'!$Q25, 2), "") | N25: =IF(Saldos_Capital_Mensual!M25>0, ROUND(Saldos_Capital_Mensual!M25 * 'Resumen_Cartera'!$Q25, 2), "") | O25: =IF(Saldos_Capital_Mensual!N25>0, ROUND(Saldos_Capital_Mensual!N25 * 'Resumen_Cartera'!$Q25, 2), "") | P25: =IF(Saldos_Capital_Mensual!O25>0, ROUND(Saldos_Capital_Mensual!O25 * 'Resumen_Cartera'!$Q25, 2), "") | Q25: =IF(Saldos_Capital_Mensual!P25>0, ROUND(Saldos_Capital_Mensual!P25 * 'Resumen_Cartera'!$Q25, 2), "") | ... T25: =IF(Saldos_Capital_Mensual!S25>0, ROUND(Saldos_Capital_Mensual!S25 * 'Resumen_Cartera'!$Q25, 2), "") | U25: =SUM(I25:T25)
A26: 0546-0008 | B26: Norma Elena Bonilla Lupio | C26: JT MOJAVE 4X4 | D26: ACTIVO | E26: 2026-01-08 | F26: 2028-01-08 | G26: 24 | H26: 817760.17 | I26: =ROUND('Resumen_Cartera'!$K26 * 'Resumen_Cartera'!$Q26, 2) | J26: =IF(Saldos_Capital_Mensual!I26>0, ROUND(Saldos_Capital_Mensual!I26 * 'Resumen_Cartera'!$Q26, 2), "") | K26: =IF(Saldos_Capital_Mensual!J26>0, ROUND(Saldos_Capital_Mensual!J26 * 'Resumen_Cartera'!$Q26, 2), "") | L26: =IF(Saldos_Capital_Mensual!K26>0, ROUND(Saldos_Capital_Mensual!K26 * 'Resumen_Cartera'!$Q26, 2), "") | M26: =IF(Saldos_Capital_Mensual!L26>0, ROUND(Saldos_Capital_Mensual!L26 * 'Resumen_Cartera'!$Q26, 2), "") | N26: =IF(Saldos_Capital_Mensual!M26>0, ROUND(Saldos_Capital_Mensual!M26 * 'Resumen_Cartera'!$Q26, 2), "") | O26: =IF(Saldos_Capital_Mensual!N26>0, ROUND(Saldos_Capital_Mensual!N26 * 'Resumen_Cartera'!$Q26, 2), "") | P26: =IF(Saldos_Capital_Mensual!O26>0, ROUND(Saldos_Capital_Mensual!O26 * 'Resumen_Cartera'!$Q26, 2), "") | Q26: =IF(Saldos_Capital_Mensual!P26>0, ROUND(Saldos_Capital_Mensual!P26 * 'Resumen_Cartera'!$Q26, 2), "") | ... T26: =IF(Saldos_Capital_Mensual!S26>0, ROUND(Saldos_Capital_Mensual!S26 * 'Resumen_Cartera'!$Q26, 2), "") | U26: =SUM(I26:T26)
A27: 0546-0009 | B27: Norma Elena Bonilla Lupio | C27: Ram 1200 Tradesman 2026 | D27: ACTIVO | E27: 2026-07-01 | F27: 2028-07-01 | G27: 24 | H27: 270028.97 | O27: =ROUND('Resumen_Cartera'!$K27 * 'Resumen_Cartera'!$Q27, 2) | P27: =IF(Saldos_Capital_Mensual!O27>0, ROUND(Saldos_Capital_Mensual!O27 * 'Resumen_Cartera'!$Q27, 2), "") | Q27: =IF(Saldos_Capital_Mensual!P27>0, ROUND(Saldos_Capital_Mensual!P27 * 'Resumen_Cartera'!$Q27, 2), "") | R27: =IF(Saldos_Capital_Mensual!Q27>0, ROUND(Saldos_Capital_Mensual!Q27 * 'Resumen_Cartera'!$Q27, 2), "") | S27: =IF(Saldos_Capital_Mensual!R27>0, ROUND(Saldos_Capital_Mensual!R27 * 'Resumen_Cartera'!$Q27, 2), "") | T27: =IF(Saldos_Capital_Mensual!S27>0, ROUND(Saldos_Capital_Mensual!S27 * 'Resumen_Cartera'!$Q27, 2), "") | U27: =SUM(I27:T27)
A28: 0551-0002 | B28: Agaveros Unidos de Tequila Jalisco Aun S de RL de Cv | C28: Ram 700 Laramie | D28: ACTIVO | E28: 2023-07-07 | F28: 2027-07-07 | G28: 48 | H28: 247353.45 | I28: =ROUND(169189.16 * 'Resumen_Cartera'!$Q28, 2) | J28: =IF(Saldos_Capital_Mensual!I28>0, ROUND(Saldos_Capital_Mensual!I28 * 'Resumen_Cartera'!$Q28, 2), "") | K28: =IF(Saldos_Capital_Mensual!J28>0, ROUND(Saldos_Capital_Mensual!J28 * 'Resumen_Cartera'!$Q28, 2), "") | L28: =IF(Saldos_Capital_Mensual!K28>0, ROUND(Saldos_Capital_Mensual!K28 * 'Resumen_Cartera'!$Q28, 2), "") | M28: =IF(Saldos_Capital_Mensual!L28>0, ROUND(Saldos_Capital_Mensual!L28 * 'Resumen_Cartera'!$Q28, 2), "") | N28: =IF(Saldos_Capital_Mensual!M28>0, ROUND(Saldos_Capital_Mensual!M28 * 'Resumen_Cartera'!$Q28, 2), "") | O28: =IF(Saldos_Capital_Mensual!N28>0, ROUND(Saldos_Capital_Mensual!N28 * 'Resumen_Cartera'!$Q28, 2), "") | P28: =IF(Saldos_Capital_Mensual!O28>0, ROUND(Saldos_Capital_Mensual!O28 * 'Resumen_Cartera'!$Q28, 2), "") | Q28: =IF(Saldos_Capital_Mensual!P28>0, ROUND(Saldos_Capital_Mensual!P28 * 'Resumen_Cartera'!$Q28, 2), "") | ... T28: =IF(Saldos_Capital_Mensual!S28>0, ROUND(Saldos_Capital_Mensual!S28 * 'Resumen_Cartera'!$Q28, 2), "") | U28: =SUM(I28:T28)
A29: 0552-0018 | B29: Transportes y Maniobras Portuarias | C29: Raizer | D29: ACTIVO | E29: 2024-11-29 | F29: 2026-11-29 | G29: 24 | H29: 720900 | I29: =ROUND(361248.01 * 'Resumen_Cartera'!$Q29, 2) | J29: =IF(Saldos_Capital_Mensual!I29>0, ROUND(Saldos_Capital_Mensual!I29 * 'Resumen_Cartera'!$Q29, 2), "") | K29: =IF(Saldos_Capital_Mensual!J29>0, ROUND(Saldos_Capital_Mensual!J29 * 'Resumen_Cartera'!$Q29, 2), "") | L29: =IF(Saldos_Capital_Mensual!K29>0, ROUND(Saldos_Capital_Mensual!K29 * 'Resumen_Cartera'!$Q29, 2), "") | M29: =IF(Saldos_Capital_Mensual!L29>0, ROUND(Saldos_Capital_Mensual!L29 * 'Resumen_Cartera'!$Q29, 2), "") | N29: =IF(Saldos_Capital_Mensual!M29>0, ROUND(Saldos_Capital_Mensual!M29 * 'Resumen_Cartera'!$Q29, 2), "") | O29: =IF(Saldos_Capital_Mensual!N29>0, ROUND(Saldos_Capital_Mensual!N29 * 'Resumen_Cartera'!$Q29, 2), "") | P29: =IF(Saldos_Capital_Mensual!O29>0, ROUND(Saldos_Capital_Mensual!O29 * 'Resumen_Cartera'!$Q29, 2), "") | Q29: =IF(Saldos_Capital_Mensual!P29>0, ROUND(Saldos_Capital_Mensual!P29 * 'Resumen_Cartera'!$Q29, 2), "") | R29: =IF(Saldos_Capital_Mensual!Q29>0, ROUND(Saldos_Capital_Mensual!Q29 * 'Resumen_Cartera'!$Q29, 2), "") | U29: =SUM(I29:T29)
A30: 0552-0019 | B30: Transportes y Maniobras Portuarias de Mexico Sa de Cv | C30: Remolque tipo Dolly | D30: ACTIVO | E30: 2024-12-20 | F30: 2026-12-20 | G30: 24 | H30: 219510 | I30: =ROUND(119241.47 * 'Resumen_Cartera'!$Q30, 2) | J30: =IF(Saldos_Capital_Mensual!I30>0, ROUND(Saldos_Capital_Mensual!I30 * 'Resumen_Cartera'!$Q30, 2), "") | K30: =IF(Saldos_Capital_Mensual!J30>0, ROUND(Saldos_Capital_Mensual!J30 * 'Resumen_Cartera'!$Q30, 2), "") | L30: =IF(Saldos_Capital_Mensual!K30>0, ROUND(Saldos_Capital_Mensual!K30 * 'Resumen_Cartera'!$Q30, 2), "") | M30: =IF(Saldos_Capital_Mensual!L30>0, ROUND(Saldos_Capital_Mensual!L30 * 'Resumen_Cartera'!$Q30, 2), "") | N30: =IF(Saldos_Capital_Mensual!M30>0, ROUND(Saldos_Capital_Mensual!M30 * 'Resumen_Cartera'!$Q30, 2), "") | O30: =IF(Saldos_Capital_Mensual!N30>0, ROUND(Saldos_Capital_Mensual!N30 * 'Resumen_Cartera'!$Q30, 2), "") | P30: =IF(Saldos_Capital_Mensual!O30>0, ROUND(Saldos_Capital_Mensual!O30 * 'Resumen_Cartera'!$Q30, 2), "") | Q30: =IF(Saldos_Capital_Mensual!P30>0, ROUND(Saldos_Capital_Mensual!P30 * 'Resumen_Cartera'!$Q30, 2), "") | ... S30: =IF(Saldos_Capital_Mensual!R30>0, ROUND(Saldos_Capital_Mensual!R30 * 'Resumen_Cartera'!$Q30, 2), "") | U30: =SUM(I30:T30)
