Workbook
Name CONTRATOS_LISTA: 'Reporte_Lineal'!$A$5:$A$281

Sheet Reporte_Lineal
A1: O-LEASING · UNA APP DE ORANGE CREW · Reporte Lineal de Cartera y Amortización Horizontal
A2: Contratos en vertical con amortización horizontal de Mes 1 a Mes 48 con fórmulas vivas de cálculo · Auditoría Financiera NIF C-15 / IFRS 16 · Desarrollado por Orange Crew
A3: DATOS CONTRACTUALES Y PARÁMETROS FINANCIEROS (NIF C-15 / IFRS 16) | AA3: MES 1 | AJ3: MES 2 | AS3: MES 3 | BB3: MES 4 | BK3: MES 5 | BT3: MES 6 | CC3: MES 7 | CL3: MES 8 | CU3: MES 9 | DD3: MES 10 | DM3: MES 11 | DV3: MES 12 | EE3: MES 13 | EN3: MES 14 | EW3: MES 15 | FF3: MES 16 | FO3: MES 17 | FX3: MES 18 | GG3: MES 19 | GP3: MES 20 | GY3: MES 21 | HH3: MES 22 | HQ3: MES 23 | HZ3: MES 24 | II3: MES 25 | IR3: MES 26 | JA3: MES 27 | JJ3: MES 28 | JS3: MES 29 | KB3: MES 30 | KK3: MES 31 | KT3: MES 32 | LC3: MES 33 | LL3: MES 34 | LU3: MES 35 | MD3: MES 36 | MM3: MES 37 | MV3: MES 38 | NE3: MES 39 | NN3: MES 40 | NW3: MES 41 | OF3: MES 42 | OO3: MES 43 | OX3: MES 44 | PG3: MES 45 | PP3: MES 46 | PY3: MES 47 | QH3: MES 48
A4: ID_Contrato | B4: Cliente | C4: Vehiculo | D4: Estatus | E4: Fecha_Alta | F4: Fecha_Vencimiento | G4: Plazo_Meses | H4: Valor_Sin_IVA | I4: Anticipo_Pct | J4: Anticipo_Monto | K4: Inversion_Neta | L4: Comision_Pct | M4: Comision_Apertura | N4: Renta_Sin_IVA | O4: Residual_Pct | P4: Residual_Pactado | Q4: Tasa_Mensual_Reg | R4: Tasa_Mensual_RATE | S4: Tasa_Nominal_Anual | T4: TIR_Anual_Efectiva | U4: VP_Residual | V4: Total_Interes_Leasing | W4: Total_Interes_Residual | X4: Ingreso_Financiero_Total | Y4: Ganancia_Neta | Z4: Margen_Sobre_Inv | AA4: Saldo_Inicial | AB4: Interes_Leasing | AC4: Renta | AD4: Capital | AE4: Saldo_Capital | AF4: Interes_Residual | AG4: Saldo_Residual | AH4: Ingreso_Financiero | AI4: Saldo_Cartera | AJ4: Saldo_Inicial | AK4: Interes_Leasing | AL4: Renta | AM4: Capital | AN4: Saldo_Capital | AO4: Interes_Residual | AP4: Saldo_Residual | AQ4: Ingreso_Financiero | AR4: Saldo_Cartera | AS4: Saldo_Inicial | AT4: Interes_Leasing | AU4: Renta | AV4: Capital | AW4: Saldo_Capital | AX4: Interes_Residual | AY4: Saldo_Residual | AZ4: Ingreso_Financiero | BA4: Saldo_Cartera | BB4: Saldo_Inicial | BC4: Interes_Leasing | BD4: Renta | BE4: Capital | BF4: Saldo_Capital | BG4: Interes_Residual | BH4: Saldo_Residual | BI4: Ingreso_Financiero | BJ4: Saldo_Cartera | BK4: Saldo_Inicial | BL4: Interes_Leasing | BM4: Renta | BN4: Capital | BO4: Saldo_Capital | BP4: Interes_Residual | BQ4: Saldo_Residual | BR4: Ingreso_Financiero | BS4: Saldo_Cartera | BT4: Saldo_Inicial | BU4: Interes_Leasing | BV4: Renta | BW4: Capital | BX4: Saldo_Capital | BY4: Interes_Residual | BZ4: Saldo_Residual | CA4: Ingreso_Financiero | CB4: Saldo_Cartera | CC4: Saldo_Inicial | CD4: Interes_Leasing | CE4: Renta | CF4: Capital | CG4: Saldo_Capital | CH4: Interes_Residual | CI4: Saldo_Residual | CJ4: Ingreso_Financiero | CK4: Saldo_Cartera | CL4: Saldo_Inicial | CM4: Interes_Leasing | CN4: Renta | CO4: Capital | CP4: Saldo_Capital | CQ4: Interes_Residual | CR4: Saldo_Residual | CS4: Ingreso_Financiero | CT4: Saldo_Cartera | CU4: Saldo_Inicial | CV4: Interes_Leasing | CW4: Renta | CX4: Capital | CY4: Saldo_Capital | CZ4: Interes_Residual | DA4: Saldo_Residual | DB4: Ingreso_Financiero | DC4: Saldo_Cartera | DD4: Saldo_Inicial | DE4: Interes_Leasing | DF4: Renta | DG4: Capital | DH4: Saldo_Capital | DI4: Interes_Residual | DJ4: Saldo_Residual | DK4: Ingreso_Financiero | DL4: Saldo_Cartera | DM4: Saldo_Inicial | DN4: Interes_Leasing | DO4: Renta | DP4: Capital | DQ4: Saldo_Capital | DR4: Interes_Residual | DS4: Saldo_Residual | DT4: Ingreso_Financiero | DU4: Saldo_Cartera | DV4: Saldo_Inicial | DW4: Interes_Leasing | DX4: Renta | DY4: Capital | DZ4: Saldo_Capital | EA4: Interes_Residual | EB4: Saldo_Residual | EC4: Ingreso_Financiero | ED4: Saldo_Cartera | EE4: Saldo_Inicial | EF4: Interes_Leasing | EG4: Renta | EH4: Capital | EI4: Saldo_Capital | EJ4: Interes_Residual | EK4: Saldo_Residual | EL4: Ingreso_Financiero | EM4: Saldo_Cartera | EN4: Saldo_Inicial | EO4: Interes_Leasing | EP4: Renta | EQ4: Capital | ER4: Saldo_Capital | ES4: Interes_Residual | ET4: Saldo_Residual | EU4: Ingreso_Financiero | EV4: Saldo_Cartera | EW4: Saldo_Inicial | EX4: Interes_Leasing | EY4: Renta | EZ4: Capital | FA4: Saldo_Capital | FB4: Interes_Residual | FC4: Saldo_Residual | FD4: Ingreso_Financiero | FE4: Saldo_Cartera | FF4: Saldo_Inicial | FG4: Interes_Leasing | FH4: Renta | FI4: Capital | FJ4: Saldo_Capital | FK4: Interes_Residual | FL4: Saldo_Residual | FM4: Ingreso_Financiero | FN4: Saldo_Cartera | FO4: Saldo_Inicial | FP4: Interes_Leasing | FQ4: Renta | FR4: Capital | FS4: Saldo_Capital | FT4: Interes_Residual | FU4: Saldo_Residual | FV4: Ingreso_Financiero | FW4: Saldo_Cartera | FX4: Saldo_Inicial | FY4: Interes_Leasing | FZ4: Renta | GA4: Capital | GB4: Saldo_Capital | GC4: Interes_Residual | GD4: Saldo_Residual | GE4: Ingreso_Financiero | GF4: Saldo_Cartera | GG4: Saldo_Inicial | GH4: Interes_Leasing | GI4: Renta | GJ4: Capital | GK4: Saldo_Capital | GL4: Interes_Residual | GM4: Saldo_Residual | GN4: Ingreso_Financiero | GO4: Saldo_Cartera | GP4: Saldo_Inicial | GQ4: Interes_Leasing | GR4: Renta | GS4: Capital | GT4: Saldo_Capital | GU4: Interes_Residual | GV4: Saldo_Residual | GW4: Ingreso_Financiero | GX4: Saldo_Cartera | GY4: Saldo_Inicial | GZ4: Interes_Leasing | HA4: Renta | HB4: Capital | HC4: Saldo_Capital | HD4: Interes_Residual | HE4: Saldo_Residual | HF4: Ingreso_Financiero | HG4: Saldo_Cartera | HH4: Saldo_Inicial | HI4: Interes_Leasing | HJ4: Renta | HK4: Capital | HL4: Saldo_Capital | HM4: Interes_Residual | HN4: Saldo_Residual | HO4: Ingreso_Financiero | HP4: Saldo_Cartera | HQ4: Saldo_Inicial | HR4: Interes_Leasing | HS4: Renta | HT4: Capital | HU4: Saldo_Capital | HV4: Interes_Residual | HW4: Saldo_Residual | HX4: Ingreso_Financiero | HY4: Saldo_Cartera | HZ4: Saldo_Inicial | IA4: Interes_Leasing | IB4: Renta | IC4: Capital | ID4: Saldo_Capital | IE4: Interes_Residual | IF4: Saldo_Residual | IG4: Ingreso_Financiero | IH4: Saldo_Cartera | II4: Saldo_Inicial | IJ4: Interes_Leasing | IK4: Renta | IL4: Capital | IM4: Saldo_Capital | IN4: Interes_Residual | IO4: Saldo_Residual | IP4: Ingreso_Financiero | IQ4: Saldo_Cartera | IR4: Saldo_Inicial | IS4: Interes_Leasing | IT4: Renta | IU4: Capital | IV4: Saldo_Capital | IW4: Interes_Residual | IX4: Saldo_Residual | IY4: Ingreso_Financiero | IZ4: Saldo_Cartera | JA4: Saldo_Inicial | JB4: Interes_Leasing | JC4: Renta | JD4: Capital | JE4: Saldo_Capital | JF4: Interes_Residual | JG4: Saldo_Residual | JH4: Ingreso_Financiero | JI4: Saldo_Cartera | JJ4: Saldo_Inicial | JK4: Interes_Leasing | JL4: Renta | JM4: Capital | JN4: Saldo_Capital | JO4: Interes_Residual | JP4: Saldo_Residual | JQ4: Ingreso_Financiero | JR4: Saldo_Cartera | JS4: Saldo_Inicial | JT4: Interes_Leasing | JU4: Renta | JV4: Capital | JW4: Saldo_Capital | JX4: Interes_Residual | JY4: Saldo_Residual | JZ4: Ingreso_Financiero | KA4: Saldo_Cartera | KB4: Saldo_Inicial | KC4: Interes_Leasing | KD4: Renta | KE4: Capital | KF4: Saldo_Capital | KG4: Interes_Residual | KH4: Saldo_Residual | KI4: Ingreso_Financiero | KJ4: Saldo_Cartera | KK4: Saldo_Inicial | KL4: Interes_Leasing | KM4: Renta | KN4: Capital | KO4: Saldo_Capital | KP4: Interes_Residual | KQ4: Saldo_Residual | KR4: Ingreso_Financiero | KS4: Saldo_Cartera | KT4: Saldo_Inicial | KU4: Interes_Leasing | KV4: Renta | KW4: Capital | KX4: Saldo_Capital | KY4: Interes_Residual | KZ4: Saldo_Residual | LA4: Ingreso_Financiero | LB4: Saldo_Cartera | LC4: Saldo_Inicial | LD4: Interes_Leasing | LE4: Renta | LF4: Capital | LG4: Saldo_Capital | LH4: Interes_Residual | LI4: Saldo_Residual | LJ4: Ingreso_Financiero | LK4: Saldo_Cartera | LL4: Saldo_Inicial | LM4: Interes_Leasing | LN4: Renta | LO4: Capital | LP4: Saldo_Capital | LQ4: Interes_Residual | LR4: Saldo_Residual | LS4: Ingreso_Financiero | LT4: Saldo_Cartera | LU4: Saldo_Inicial | LV4: Interes_Leasing | LW4: Renta | LX4: Capital | LY4: Saldo_Capital | LZ4: Interes_Residual | MA4: Saldo_Residual | MB4: Ingreso_Financiero | MC4: Saldo_Cartera | MD4: Saldo_Inicial | ME4: Interes_Leasing | MF4: Renta | MG4: Capital | MH4: Saldo_Capital | MI4: Interes_Residual | MJ4: Saldo_Residual | MK4: Ingreso_Financiero | ML4: Saldo_Cartera | MM4: Saldo_Inicial | MN4: Interes_Leasing | MO4: Renta | MP4: Capital | MQ4: Saldo_Capital | MR4: Interes_Residual | MS4: Saldo_Residual | MT4: Ingreso_Financiero | MU4: Saldo_Cartera | MV4: Saldo_Inicial | MW4: Interes_Leasing | MX4: Renta | MY4: Capital | MZ4: Saldo_Capital | NA4: Interes_Residual | NB4: Saldo_Residual | NC4: Ingreso_Financiero | ND4: Saldo_Cartera | NE4: Saldo_Inicial | NF4: Interes_Leasing | NG4: Renta | NH4: Capital | NI4: Saldo_Capital | NJ4: Interes_Residual | NK4: Saldo_Residual | NL4: Ingreso_Financiero | NM4: Saldo_Cartera | NN4: Saldo_Inicial | NO4: Interes_Leasing | NP4: Renta | NQ4: Capital | NR4: Saldo_Capital | NS4: Interes_Residual | NT4: Saldo_Residual | NU4: Ingreso_Financiero | NV4: Saldo_Cartera | NW4: Saldo_Inicial | NX4: Interes_Leasing | NY4: Renta | NZ4: Capital | OA4: Saldo_Capital | OB4: Interes_Residual | OC4: Saldo_Residual | OD4: Ingreso_Financiero | OE4: Saldo_Cartera | OF4: Saldo_Inicial | OG4: Interes_Leasing | OH4: Renta | OI4: Capital | OJ4: Saldo_Capital | OK4: Interes_Residual | OL4: Saldo_Residual | OM4: Ingreso_Financiero | ON4: Saldo_Cartera | OO4: Saldo_Inicial | OP4: Interes_Leasing | OQ4: Renta | OR4: Capital | OS4: Saldo_Capital | OT4: Interes_Residual | OU4: Saldo_Residual | OV4: Ingreso_Financiero | OW4: Saldo_Cartera | OX4: Saldo_Inicial | OY4: Interes_Leasing | OZ4: Renta | PA4: Capital | PB4: Saldo_Capital | PC4: Interes_Residual | PD4: Saldo_Residual | PE4: Ingreso_Financiero | PF4: Saldo_Cartera | PG4: Saldo_Inicial | PH4: Interes_Leasing | PI4: Renta | PJ4: Capital | PK4: Saldo_Capital | PL4: Interes_Residual | PM4: Saldo_Residual | PN4: Ingreso_Financiero | PO4: Saldo_Cartera | PP4: Saldo_Inicial | PQ4: Interes_Leasing | PR4: Renta | PS4: Capital | PT4: Saldo_Capital | PU4: Interes_Residual | PV4: Saldo_Residual | PW4: Ingreso_Financiero | PX4: Saldo_Cartera | PY4: Saldo_Inicial | PZ4: Interes_Leasing | QA4: Renta | QB4: Capital | QC4: Saldo_Capital | QD4: Interes_Residual | QE4: Saldo_Residual | QF4: Ingreso_Financiero | QG4: Saldo_Cartera | QH4: Saldo_Inicial | QI4: Interes_Leasing | QJ4: Renta | QK4: Capital | QL4: Saldo_Capital | QM4: Interes_Residual | QN4: Saldo_Residual | QO4: Ingreso_Financiero | QP4: Saldo_Cartera
A5: 0326-0003 | B5: Alberto Vázquez Solorio | C5: Volkswagen Tiguan R-Line 2026 | D5: ACTIVO | E5: 2026-09-16 | F5: 2030-09-16 | G5: 48 | H5: 645181.9 | I5: 0.3705 | J5: =ROUND(H5*I5, 2) | K5: =ROUND(H5-J5, 2) | L5: 0 | M5: =ROUND(H5*L5, 2) | N5: 8393.91 | O5: 0.28 | P5: =ROUND(H5*O5, 2) | Q5: 0.01206146 | R5: =RATE(G5, -N5, K5, -P5) | S5: =ROUND(Q5*12, 8) | T5: =ROUND(((1+Q5)^12)-1, 8) | U5: =ROUND(PV(Q5, G5, 0, -P5), 2) | V5: =SUMIF($AA$4:$QP$4, "Interes_Leasing", AA5:QP5) | W5: =SUMIF($AA$4:$QP$4, "Interes_Residual", AA5:QP5) | X5: =ROUND(V5+W5, 2) | Y5: =ROUND((N5*G5+P5+M5)-K5, 2) | Z5: =ROUND(Y5/K5, 4) | AA5: =IF(1<=$G5, $K5, "") | AB5: =IF(1<=$G5, ROUND(AA5*$Q5, 2), "") | AC5: =IF(1<=$G5, $N5, "") | AD5: =IF(1<=$G5, AC5-AB5, "") | AE5: =IF(1<=$G5, AA5-AD5, "") | AF5: =IF(1<=$G5, ROUND($U5*$Q5, 2), "") | AG5: =IF(1<=$G5, $U5+AF5, "") | AH5: =IF(1<=$G5, AB5+AF5, "") | AI5: =IF(1<=$G5, ($G5-1)*$N5, "") | AJ5: =IF(2<=$G5, AE5, "") | AK5: =IF(2<=$G5, ROUND(AJ5*$Q5, 2), "") | AL5: =IF(2<=$G5, $N5, "") | AM5: =IF(2<=$G5, AL5-AK5, "") | AN5: =IF(2<=$G5, AJ5-AM5, "") | AO5: =IF(2<=$G5, ROUND(AG5*$Q5, 2), "") | AP5: =IF(2<=$G5, AG5+AO5, "") | AQ5: =IF(2<=$G5, AK5+AO5, "") | AR5: =IF(2<=$G5, ($G5-2)*$N5, "") | AS5: =IF(3<=$G5, AN5, "") | AT5: =IF(3<=$G5, ROUND(AS5*$Q5, 2), "") | AU5: =IF(3<=$G5, $N5, "") | AV5: =IF(3<=$G5, AU5-AT5, "") | AW5: =IF(3<=$G5, AS5-AV5, "") | AX5: =IF(3<=$G5, ROUND(AP5*$Q5, 2), "") | AY5: =IF(3<=$G5, AP5+AX5, "") | AZ5: =IF(3<=$G5, AT5+AX5, "") | BA5: =IF(3<=$G5, ($G5-3)*$N5, "") | BB5: =IF(4<=$G5, AW5, "") | BC5: =IF(4<=$G5, ROUND(BB5*$Q5, 2), "") | BD5: =IF(4<=$G5, $N5, "") | BE5: =IF(4<=$G5, BD5-BC5, "") | BF5: =IF(4<=$G5, BB5-BE5, "") | BG5: =IF(4<=$G5, ROUND(AY5*$Q5, 2), "") | BH5: =IF(4<=$G5, AY5+BG5, "") | BI5: =IF(4<=$G5, BC5+BG5, "") | BJ5: =IF(4<=$G5, ($G5-4)*$N5, "") | BK5: =IF(5<=$G5, BF5, "") | BL5: =IF(5<=$G5, ROUND(BK5*$Q5, 2), "") | BM5: =IF(5<=$G5, $N5, "") | BN5: =IF(5<=$G5, BM5-BL5, "") | BO5: =IF(5<=$G5, BK5-BN5, "") | BP5: =IF(5<=$G5, ROUND(BH5*$Q5, 2), "") | BQ5: =IF(5<=$G5, BH5+BP5, "") | BR5: =IF(5<=$G5, BL5+BP5, "") | BS5: =IF(5<=$G5, ($G5-5)*$N5, "") | BT5: =IF(6<=$G5, BO5, "") | BU5: =IF(6<=$G5, ROUND(BT5*$Q5, 2), "") | BV5: =IF(6<=$G5, $N5, "") | BW5: =IF(6<=$G5, BV5-BU5, "") | BX5: =IF(6<=$G5, BT5-BW5, "") | BY5: =IF(6<=$G5, ROUND(BQ5*$Q5, 2), "") | BZ5: =IF(6<=$G5, BQ5+BY5, "") | CA5: =IF(6<=$G5, BU5+BY5, "") | CB5: =IF(6<=$G5, ($G5-6)*$N5, "") | CC5: =IF(7<=$G5, BX5, "") | CD5: =IF(7<=$G5, ROUND(CC5*$Q5, 2), "") | CE5: =IF(7<=$G5, $N5, "") | CF5: =IF(7<=$G5, CE5-CD5, "") | CG5: =IF(7<=$G5, CC5-CF5, "") | CH5: =IF(7<=$G5, ROUND(BZ5*$Q5, 2), "") | CI5: =IF(7<=$G5, BZ5+CH5, "") | CJ5: =IF(7<=$G5, CD5+CH5, "") | CK5: =IF(7<=$G5, ($G5-7)*$N5, "") | CL5: =IF(8<=$G5, CG5, "") | CM5: =IF(8<=$G5, ROUND(CL5*$Q5, 2), "") | CN5: =IF(8<=$G5, $N5, "") | CO5: =IF(8<=$G5, CN5-CM5, "") | CP5: =IF(8<=$G5, CL5-CO5, "") | CQ5: =IF(8<=$G5, ROUND(CI5*$Q5, 2), "") | CR5: =IF(8<=$G5, CI5+CQ5, "") | CS5: =IF(8<=$G5, CM5+CQ5, "") | CT5: =IF(8<=$G5, ($G5-8)*$N5, "") | CU5: =IF(9<=$G5, CP5, "") | CV5: =IF(9<=$G5, ROUND(CU5*$Q5, 2), "") | CW5: =IF(9<=$G5, $N5, "") | CX5: =IF(9<=$G5, CW5-CV5, "") | CY5: =IF(9<=$G5, CU5-CX5, "") | CZ5: =IF(9<=$G5, ROUND(CR5*$Q5, 2), "") | DA5: =IF(9<=$G5, CR5+CZ5, "") | DB5: =IF(9<=$G5, CV5+CZ5, "") | DC5: =IF(9<=$G5, ($G5-9)*$N5, "") | DD5: =IF(10<=$G5, CY5, "") | DE5: =IF(10<=$G5, ROUND(DD5*$Q5, 2), "") | DF5: =IF(10<=$G5, $N5, "") | DG5: =IF(10<=$G5, DF5-DE5, "") | DH5: =IF(10<=$G5, DD5-DG5, "") | DI5: =IF(10<=$G5, ROUND(DA5*$Q5, 2), "") | DJ5: =IF(10<=$G5, DA5+DI5, "") | DK5: =IF(10<=$G5, DE5+DI5, "") | DL5: =IF(10<=$G5, ($G5-10)*$N5, "") | DM5: =IF(11<=$G5, DH5, "") | DN5: =IF(11<=$G5, ROUND(DM5*$Q5, 2), "") | DO5: =IF(11<=$G5, $N5, "") | DP5: =IF(11<=$G5, DO5-DN5, "") | DQ5: =IF(11<=$G5, DM5-DP5, "") | DR5: =IF(11<=$G5, ROUND(DJ5*$Q5, 2), "") | DS5: =IF(11<=$G5, DJ5+DR5, "") | DT5: =IF(11<=$G5, DN5+DR5, "") | DU5: =IF(11<=$G5, ($G5-11)*$N5, "") | DV5: =IF(12<=$G5, DQ5, "") | DW5: =IF(12<=$G5, ROUND(DV5*$Q5, 2), "") | DX5: =IF(12<=$G5, $N5, "") | DY5: =IF(12<=$G5, DX5-DW5, "") | DZ5: =IF(12<=$G5, DV5-DY5, "") | EA5: =IF(12<=$G5, ROUND(DS5*$Q5, 2), "") | EB5: =IF(12<=$G5, DS5+EA5, "") | EC5: =IF(12<=$G5, DW5+EA5, "") | ED5: =IF(12<=$G5, ($G5-12)*$N5, "") | EE5: =IF(13<=$G5, DZ5, "") | EF5: =IF(13<=$G5, ROUND(EE5*$Q5, 2), "") | EG5: =IF(13<=$G5, $N5, "") | EH5: =IF(13<=$G5, EG5-EF5, "") | EI5: =IF(13<=$G5, EE5-EH5, "") | EJ5: =IF(13<=$G5, ROUND(EB5*$Q5, 2), "") | EK5: =IF(13<=$G5, EB5+EJ5, "") | EL5: =IF(13<=$G5, EF5+EJ5, "") | EM5: =IF(13<=$G5, ($G5-13)*$N5, "") | EN5: =IF(14<=$G5, EI5, "") | EO5: =IF(14<=$G5, ROUND(EN5*$Q5, 2), "") | EP5: =IF(14<=$G5, $N5, "") | EQ5: =IF(14<=$G5, EP5-EO5, "") | ER5: =IF(14<=$G5, EN5-EQ5, "") | ES5: =IF(14<=$G5, ROUND(EK5*$Q5, 2), "") | ET5: =IF(14<=$G5, EK5+ES5, "") | EU5: =IF(14<=$G5, EO5+ES5, "") | EV5: =IF(14<=$G5, ($G5-14)*$N5, "") | EW5: =IF(15<=$G5, ER5, "") | EX5: =IF(15<=$G5, ROUND(EW5*$Q5, 2), "") | EY5: =IF(15<=$G5, $N5, "") | EZ5: =IF(15<=$G5, EY5-EX5, "") | FA5: =IF(15<=$G5, EW5-EZ5, "") | FB5: =IF(15<=$G5, ROUND(ET5*$Q5, 2), "") | FC5: =IF(15<=$G5, ET5+FB5, "") | FD5: =IF(15<=$G5, EX5+FB5, "") | FE5: =IF(15<=$G5, ($G5-15)*$N5, "") | FF5: =IF(16<=$G5, FA5, "") | FG5: =IF(16<=$G5, ROUND(FF5*$Q5, 2), "") | FH5: =IF(16<=$G5, $N5, "") | FI5: =IF(16<=$G5, FH5-FG5, "") | FJ5: =IF(16<=$G5, FF5-FI5, "") | FK5: =IF(16<=$G5, ROUND(FC5*$Q5, 2), "") | FL5: =IF(16<=$G5, FC5+FK5, "") | FM5: =IF(16<=$G5, FG5+FK5, "") | FN5: =IF(16<=$G5, ($G5-16)*$N5, "") | FO5: =IF(17<=$G5, FJ5, "") | FP5: =IF(17<=$G5, ROUND(FO5*$Q5, 2), "") | FQ5: =IF(17<=$G5, $N5, "") | FR5: =IF(17<=$G5, FQ5-FP5, "") | FS5: =IF(17<=$G5, FO5-FR5, "") | FT5: =IF(17<=$G5, ROUND(FL5*$Q5, 2), "") | FU5: =IF(17<=$G5, FL5+FT5, "") | FV5: =IF(17<=$G5, FP5+FT5, "") | FW5: =IF(17<=$G5, ($G5-17)*$N5, "") | FX5: =IF(18<=$G5, FS5, "") | FY5: =IF(18<=$G5, ROUND(FX5*$Q5, 2), "") | FZ5: =IF(18<=$G5, $N5, "") | GA5: =IF(18<=$G5, FZ5-FY5, "") | GB5: =IF(18<=$G5, FX5-GA5, "") | GC5: =IF(18<=$G5, ROUND(FU5*$Q5, 2), "") | GD5: =IF(18<=$G5, FU5+GC5, "") | GE5: =IF(18<=$G5, FY5+GC5, "") | GF5: =IF(18<=$G5, ($G5-18)*$N5, "") | GG5: =IF(19<=$G5, GB5, "") | GH5: =IF(19<=$G5, ROUND(GG5*$Q5, 2), "") | GI5: =IF(19<=$G5, $N5, "") | GJ5: =IF(19<=$G5, GI5-GH5, "") | GK5: =IF(19<=$G5, GG5-GJ5, "") | GL5: =IF(19<=$G5, ROUND(GD5*$Q5, 2), "") | GM5: =IF(19<=$G5, GD5+GL5, "") | GN5: =IF(19<=$G5, GH5+GL5, "") | GO5: =IF(19<=$G5, ($G5-19)*$N5, "") | GP5: =IF(20<=$G5, GK5, "") | GQ5: =IF(20<=$G5, ROUND(GP5*$Q5, 2), "") | GR5: =IF(20<=$G5, $N5, "") | GS5: =IF(20<=$G5, GR5-GQ5, "") | GT5: =IF(20<=$G5, GP5-GS5, "") | GU5: =IF(20<=$G5, ROUND(GM5*$Q5, 2), "") | GV5: =IF(20<=$G5, GM5+GU5, "") | GW5: =IF(20<=$G5, GQ5+GU5, "") | GX5: =IF(20<=$G5, ($G5-20)*$N5, "") | GY5: =IF(21<=$G5, GT5, "") | GZ5: =IF(21<=$G5, ROUND(GY5*$Q5, 2), "") | HA5: =IF(21<=$G5, $N5, "") | HB5: =IF(21<=$G5, HA5-GZ5, "") | HC5: =IF(21<=$G5, GY5-HB5, "") | HD5: =IF(21<=$G5, ROUND(GV5*$Q5, 2), "") | HE5: =IF(21<=$G5, GV5+HD5, "") | HF5: =IF(21<=$G5, GZ5+HD5, "") | HG5: =IF(21<=$G5, ($G5-21)*$N5, "") | HH5: =IF(22<=$G5, HC5, "") | HI5: =IF(22<=$G5, ROUND(HH5*$Q5, 2), "") | HJ5: =IF(22<=$G5, $N5, "") | HK5: =IF(22<=$G5, HJ5-HI5, "") | HL5: =IF(22<=$G5, HH5-HK5, "") | HM5: =IF(22<=$G5, ROUND(HE5*$Q5, 2), "") | HN5: =IF(22<=$G5, HE5+HM5, "") | HO5: =IF(22<=$G5, HI5+HM5, "") | HP5: =IF(22<=$G5, ($G5-22)*$N5, "") | HQ5: =IF(23<=$G5, HL5, "") | HR5: =IF(23<=$G5, ROUND(HQ5*$Q5, 2), "") | HS5: =IF(23<=$G5, $N5, "") | HT5: =IF(23<=$G5, HS5-HR5, "") | HU5: =IF(23<=$G5, HQ5-HT5, "") | HV5: =IF(23<=$G5, ROUND(HN5*$Q5, 2), "") | HW5: =IF(23<=$G5, HN5+HV5, "") | HX5: =IF(23<=$G5, HR5+HV5, "") | HY5: =IF(23<=$G5, ($G5-23)*$N5, "") | HZ5: =IF(24<=$G5, HU5, "") | IA5: =IF(24<=$G5, ROUND(HZ5*$Q5, 2), "") | IB5: =IF(24<=$G5, $N5, "") | IC5: =IF(24<=$G5, IB5-IA5, "") | ID5: =IF(24<=$G5, HZ5-IC5, "") | IE5: =IF(24<=$G5, ROUND(HW5*$Q5, 2), "") | IF5: =IF(24<=$G5, HW5+IE5, "") | IG5: =IF(24<=$G5, IA5+IE5, "") | IH5: =IF(24<=$G5, ($G5-24)*$N5, "") | II5: =IF(25<=$G5, ID5, "") | IJ5: =IF(25<=$G5, ROUND(II5*$Q5, 2), "") | IK5: =IF(25<=$G5, $N5, "") | IL5: =IF(25<=$G5, IK5-IJ5, "") | IM5: =IF(25<=$G5, II5-IL5, "") | IN5: =IF(25<=$G5, ROUND(IF5*$Q5, 2), "") | IO5: =IF(25<=$G5, IF5+IN5, "") | IP5: =IF(25<=$G5, IJ5+IN5, "") | IQ5: =IF(25<=$G5, ($G5-25)*$N5, "") | IR5: =IF(26<=$G5, IM5, "") | IS5: =IF(26<=$G5, ROUND(IR5*$Q5, 2), "") | IT5: =IF(26<=$G5, $N5, "") | IU5: =IF(26<=$G5, IT5-IS5, "") | IV5: =IF(26<=$G5, IR5-IU5, "") | IW5: =IF(26<=$G5, ROUND(IO5*$Q5, 2), "") | IX5: =IF(26<=$G5, IO5+IW5, "") | IY5: =IF(26<=$G5, IS5+IW5, "") | IZ5: =IF(26<=$G5, ($G5-26)*$N5, "") | JA5: =IF(27<=$G5, IV5, "") | JB5: =IF(27<=$G5, ROUND(JA5*$Q5, 2), "") | JC5: =IF(27<=$G5, $N5, "") | JD5: =IF(27<=$G5, JC5-JB5, "") | JE5: =IF(27<=$G5, JA5-JD5, "") | JF5: =IF(27<=$G5, ROUND(IX5*$Q5, 2), "") | JG5: =IF(27<=$G5, IX5+JF5, "") | JH5: =IF(27<=$G5, JB5+JF5, "") | JI5: =IF(27<=$G5, ($G5-27)*$N5, "") | JJ5: =IF(28<=$G5, JE5, "") | JK5: =IF(28<=$G5, ROUND(JJ5*$Q5, 2), "") | JL5: =IF(28<=$G5, $N5, "") | JM5: =IF(28<=$G5, JL5-JK5, "") | JN5: =IF(28<=$G5, JJ5-JM5, "") | JO5: =IF(28<=$G5, ROUND(JG5*$Q5, 2), "") | JP5: =IF(28<=$G5, JG5+JO5, "") | JQ5: =IF(28<=$G5, JK5+JO5, "") | JR5: =IF(28<=$G5, ($G5-28)*$N5, "") | JS5: =IF(29<=$G5, JN5, "") | JT5: =IF(29<=$G5, ROUND(JS5*$Q5, 2), "") | JU5: =IF(29<=$G5, $N5, "") | JV5: =IF(29<=$G5, JU5-JT5, "") | JW5: =IF(29<=$G5, JS5-JV5, "") | JX5: =IF(29<=$G5, ROUND(JP5*$Q5, 2), "") | JY5: =IF(29<=$G5, JP5+JX5, "") | JZ5: =IF(29<=$G5, JT5+JX5, "") | KA5: =IF(29<=$G5, ($G5-29)*$N5, "") | KB5: =IF(30<=$G5, JW5, "") | KC5: =IF(30<=$G5, ROUND(KB5*$Q5, 2), "") | KD5: =IF(30<=$G5, $N5, "") | KE5: =IF(30<=$G5, KD5-KC5, "") | KF5: =IF(30<=$G5, KB5-KE5, "") | KG5: =IF(30<=$G5, ROUND(JY5*$Q5, 2), "") | KH5: =IF(30<=$G5, JY5+KG5, "") | KI5: =IF(30<=$G5, KC5+KG5, "") | KJ5: =IF(30<=$G5, ($G5-30)*$N5, "") | KK5: =IF(31<=$G5, KF5, "") | KL5: =IF(31<=$G5, ROUND(KK5*$Q5, 2), "") | KM5: =IF(31<=$G5, $N5, "") | KN5: =IF(31<=$G5, KM5-KL5, "") | KO5: =IF(31<=$G5, KK5-KN5, "") | KP5: =IF(31<=$G5, ROUND(KH5*$Q5, 2), "") | KQ5: =IF(31<=$G5, KH5+KP5, "") | KR5: =IF(31<=$G5, KL5+KP5, "") | KS5: =IF(31<=$G5, ($G5-31)*$N5, "") | KT5: =IF(32<=$G5, KO5, "") | KU5: =IF(32<=$G5, ROUND(KT5*$Q5, 2), "") | KV5: =IF(32<=$G5, $N5, "") | KW5: =IF(32<=$G5, KV5-KU5, "") | KX5: =IF(32<=$G5, KT5-KW5, "") | KY5: =IF(32<=$G5, ROUND(KQ5*$Q5, 2), "") | KZ5: =IF(32<=$G5, KQ5+KY5, "") | LA5: =IF(32<=$G5, KU5+KY5, "") | LB5: =IF(32<=$G5, ($G5-32)*$N5, "") | LC5: =IF(33<=$G5, KX5, "") | LD5: =IF(33<=$G5, ROUND(LC5*$Q5, 2), "") | LE5: =IF(33<=$G5, $N5, "") | LF5: =IF(33<=$G5, LE5-LD5, "") | LG5: =IF(33<=$G5, LC5-LF5, "") | LH5: =IF(33<=$G5, ROUND(KZ5*$Q5, 2), "") | LI5: =IF(33<=$G5, KZ5+LH5, "") | LJ5: =IF(33<=$G5, LD5+LH5, "") | LK5: =IF(33<=$G5, ($G5-33)*$N5, "") | LL5: =IF(34<=$G5, LG5, "") | LM5: =IF(34<=$G5, ROUND(LL5*$Q5, 2), "") | LN5: =IF(34<=$G5, $N5, "") | LO5: =IF(34<=$G5, LN5-LM5, "") | LP5: =IF(34<=$G5, LL5-LO5, "") | LQ5: =IF(34<=$G5, ROUND(LI5*$Q5, 2), "") | LR5: =IF(34<=$G5, LI5+LQ5, "") | LS5: =IF(34<=$G5, LM5+LQ5, "") | LT5: =IF(34<=$G5, ($G5-34)*$N5, "") | LU5: =IF(35<=$G5, LP5, "") | LV5: =IF(35<=$G5, ROUND(LU5*$Q5, 2), "") | LW5: =IF(35<=$G5, $N5, "") | LX5: =IF(35<=$G5, LW5-LV5, "") | LY5: =IF(35<=$G5, LU5-LX5, "") | LZ5: =IF(35<=$G5, ROUND(LR5*$Q5, 2), "") | MA5: =IF(35<=$G5, LR5+LZ5, "") | MB5: =IF(35<=$G5, LV5+LZ5, "") | MC5: =IF(35<=$G5, ($G5-35)*$N5, "") | MD5: =IF(36<=$G5, LY5, "") | ME5: =IF(36<=$G5, ROUND(MD5*$Q5, 2), "") | MF5: =IF(36<=$G5, $N5, "") | MG5: =IF(36<=$G5, MF5-ME5, "") | MH5: =IF(36<=$G5, MD5-MG5, "") | MI5: =IF(36<=$G5, ROUND(MA5*$Q5, 2), "") | MJ5: =IF(36<=$G5, MA5+MI5, "") | MK5: =IF(36<=$G5, ME5+MI5, "") | ML5: =IF(36<=$G5, ($G5-36)*$N5, "") | MM5: =IF(37<=$G5, MH5, "") | MN5: =IF(37<=$G5, ROUND(MM5*$Q5, 2), "") | MO5: =IF(37<=$G5, $N5, "") | MP5: =IF(37<=$G5, MO5-MN5, "") | MQ5: =IF(37<=$G5, MM5-MP5, "") | MR5: =IF(37<=$G5, ROUND(MJ5*$Q5, 2), "") | MS5: =IF(37<=$G5, MJ5+MR5, "") | MT5: =IF(37<=$G5, MN5+MR5, "") | MU5: =IF(37<=$G5, ($G5-37)*$N5, "") | MV5: =IF(38<=$G5, MQ5, "") | MW5: =IF(38<=$G5, ROUND(MV5*$Q5, 2), "") | MX5: =IF(38<=$G5, $N5, "") | MY5: =IF(38<=$G5, MX5-MW5, "") | MZ5: =IF(38<=$G5, MV5-MY5, "") | NA5: =IF(38<=$G5, ROUND(MS5*$Q5, 2), "") | NB5: =IF(38<=$G5, MS5+NA5, "") | NC5: =IF(38<=$G5, MW5+NA5, "") | ND5: =IF(38<=$G5, ($G5-38)*$N5, "") | NE5: =IF(39<=$G5, MZ5, "") | NF5: =IF(39<=$G5, ROUND(NE5*$Q5, 2), "") | NG5: =IF(39<=$G5, $N5, "") | NH5: =IF(39<=$G5, NG5-NF5, "") | NI5: =IF(39<=$G5, NE5-NH5, "") | NJ5: =IF(39<=$G5, ROUND(NB5*$Q5, 2), "") | NK5: =IF(39<=$G5, NB5+NJ5, "") | NL5: =IF(39<=$G5, NF5+NJ5, "") | NM5: =IF(39<=$G5, ($G5-39)*$N5, "") | NN5: =IF(40<=$G5, NI5, "") | NO5: =IF(40<=$G5, ROUND(NN5*$Q5, 2), "") | NP5: =IF(40<=$G5, $N5, "") | NQ5: =IF(40<=$G5, NP5-NO5, "") | NR5: =IF(40<=$G5, NN5-NQ5, "") | NS5: =IF(40<=$G5, ROUND(NK5*$Q5, 2), "") | NT5: =IF(40<=$G5, NK5+NS5, "") | NU5: =IF(40<=$G5, NO5+NS5, "") | NV5: =IF(40<=$G5, ($G5-40)*$N5, "") | NW5: =IF(41<=$G5, NR5, "") | NX5: =IF(41<=$G5, ROUND(NW5*$Q5, 2), "") | NY5: =IF(41<=$G5, $N5, "") | NZ5: =IF(41<=$G5, NY5-NX5, "") | OA5: =IF(41<=$G5, NW5-NZ5, "") | OB5: =IF(41<=$G5, ROUND(NT5*$Q5, 2), "") | OC5: =IF(41<=$G5, NT5+OB5, "") | OD5: =IF(41<=$G5, NX5+OB5, "") | OE5: =IF(41<=$G5, ($G5-41)*$N5, "") | OF5: =IF(42<=$G5, OA5, "") | OG5: =IF(42<=$G5, ROUND(OF5*$Q5, 2), "") | OH5: =IF(42<=$G5, $N5, "") | OI5: =IF(42<=$G5, OH5-OG5, "") | OJ5: =IF(42<=$G5, OF5-OI5, "") | OK5: =IF(42<=$G5, ROUND(OC5*$Q5, 2), "") | OL5: =IF(42<=$G5, OC5+OK5, "") | OM5: =IF(42<=$G5, OG5+OK5, "") | ON5: =IF(42<=$G5, ($G5-42)*$N5, "") | OO5: =IF(43<=$G5, OJ5, "") | OP5: =IF(43<=$G5, ROUND(OO5*$Q5, 2), "") | OQ5: =IF(43<=$G5, $N5, "") | OR5: =IF(43<=$G5, OQ5-OP5, "") | OS5: =IF(43<=$G5, OO5-OR5, "") | OT5: =IF(43<=$G5, ROUND(OL5*$Q5, 2), "") | OU5: =IF(43<=$G5, OL5+OT5, "") | OV5: =IF(43<=$G5, OP5+OT5, "") | OW5: =IF(43<=$G5, ($G5-43)*$N5, "") | OX5: =IF(44<=$G5, OS5, "") | OY5: =IF(44<=$G5, ROUND(OX5*$Q5, 2), "") | OZ5: =IF(44<=$G5, $N5, "") | PA5: =IF(44<=$G5, OZ5-OY5, "") | PB5: =IF(44<=$G5, OX5-PA5, "") | PC5: =IF(44<=$G5, ROUND(OU5*$Q5, 2), "") | PD5: =IF(44<=$G5, OU5+PC5, "") | PE5: =IF(44<=$G5, OY5+PC5, "") | PF5: =IF(44<=$G5, ($G5-44)*$N5, "") | PG5: =IF(45<=$G5, PB5, "") | PH5: =IF(45<=$G5, ROUND(PG5*$Q5, 2), "") | PI5: =IF(45<=$G5, $N5, "") | PJ5: =IF(45<=$G5, PI5-PH5, "") | PK5: =IF(45<=$G5, PG5-PJ5, "") | PL5: =IF(45<=$G5, ROUND(PD5*$Q5, 2), "") | PM5: =IF(45<=$G5, PD5+PL5, "") | PN5: =IF(45<=$G5, PH5+PL5, "") | PO5: =IF(45<=$G5, ($G5-45)*$N5, "") | PP5: =IF(46<=$G5, PK5, "") | PQ5: =IF(46<=$G5, ROUND(PP5*$Q5, 2), "") | PR5: =IF(46<=$G5, $N5, "") | PS5: =IF(46<=$G5, PR5-PQ5, "") | PT5: =IF(46<=$G5, PP5-PS5, "") | PU5: =IF(46<=$G5, ROUND(PM5*$Q5, 2), "") | PV5: =IF(46<=$G5, PM5+PU5, "") | PW5: =IF(46<=$G5, PQ5+PU5, "") | PX5: =IF(46<=$G5, ($G5-46)*$N5, "") | PY5: =IF(47<=$G5, PT5, "") | PZ5: =IF(47<=$G5, ROUND(PY5*$Q5, 2), "") | QA5: =IF(47<=$G5, $N5, "") | QB5: =IF(47<=$G5, QA5-PZ5, "") | QC5: =IF(47<=$G5, PY5-QB5, "") | QD5: =IF(47<=$G5, ROUND(PV5*$Q5, 2), "") | QE5: =IF(47<=$G5, PV5+QD5, "") | QF5: =IF(47<=$G5, PZ5+QD5, "") | QG5: =IF(47<=$G5, ($G5-47)*$N5, "") | QH5: =IF(48<=$G5, QC5, "") | QI5: =IF(48<=$G5, ROUND(QH5*$Q5, 2), "") | QJ5: =IF(48<=$G5, $N5, "") | QK5: =IF(48<=$G5, QJ5-QI5, "") | QL5: =IF(48<=$G5, QH5-QK5, "") | QM5: =IF(48<=$G5, ROUND(QE5*$Q5, 2), "") | QN5: =IF(48<=$G5, QE5+QM5, "") | QO5: =IF(48<=$G5, QI5+QM5, "") | QP5: =IF(48<=$G5, ($G5-48)*$N5, "")
A6: 0472-0003 | B6: Miguel Zazueta Beltrán | C6: Jeep Grand Cherokee | D6: ACTIVO | E6: 2026-02-03 | F6: 2029-02-03 | G6: 36 | H6: 1217433.6 | I6: 0.3 | J6: =ROUND(H6*I6, 2) | K6: =ROUND(H6-J6, 2) | L6: 0.02 | M6: =ROUND(H6*L6, 2) | N6: 35031.5 | O6: 0.1 | P6: =ROUND(H6*O6, 2) | Q6: 0.02661776 | R6: =RATE(G6, -N6, K6, -P6) | S6: =ROUND(Q6*12, 8) | T6: =ROUND(((1+Q6)^12)-1, 8) | U6: =ROUND(PV(Q6, G6, 0, -P6), 2) | V6: =SUMIF($AA$4:$QP$4, "Interes_Leasing", AA6:QP6) | W6: =SUMIF($AA$4:$QP$4, "Interes_Residual", AA6:QP6) | X6: =ROUND(V6+W6, 2) | Y6: =ROUND((N6*G6+P6+M6)-K6, 2) | Z6: =ROUND(Y6/K6, 4) | AA6: =IF(1<=$G6, $K6, "") | AB6: =IF(1<=$G6, ROUND(AA6*$Q6, 2), "") | AC6: =IF(1<=$G6, $N6, "") | AD6: =IF(1<=$G6, AC6-AB6, "") | AE6: =IF(1<=$G6, AA6-AD6, "") | AF6: =IF(1<=$G6, ROUND($U6*$Q6, 2), "") | AG6: =IF(1<=$G6, $U6+AF6, "") | AH6: =IF(1<=$G6, AB6+AF6, "") | AI6: =IF(1<=$G6, ($G6-1)*$N6, "") | AJ6: =IF(2<=$G6, AE6, "") | AK6: =IF(2<=$G6, ROUND(AJ6*$Q6, 2), "") | AL6: =IF(2<=$G6, $N6, "") | AM6: =IF(2<=$G6, AL6-AK6, "") | AN6: =IF(2<=$G6, AJ6-AM6, "") | AO6: =IF(2<=$G6, ROUND(AG6*$Q6, 2), "") | AP6: =IF(2<=$G6, AG6+AO6, "") | AQ6: =IF(2<=$G6, AK6+AO6, "") | AR6: =IF(2<=$G6, ($G6-2)*$N6, "") | AS6: =IF(3<=$G6, AN6, "") | AT6: =IF(3<=$G6, ROUND(AS6*$Q6, 2), "") | AU6: =IF(3<=$G6, $N6, "") | AV6: =IF(3<=$G6, AU6-AT6, "") | AW6: =IF(3<=$G6, AS6-AV6, "") | AX6: =IF(3<=$G6, ROUND(AP6*$Q6, 2), "") | AY6: =IF(3<=$G6, AP6+AX6, "") | AZ6: =IF(3<=$G6, AT6+AX6, "") | BA6: =IF(3<=$G6, ($G6-3)*$N6, "") | BB6: =IF(4<=$G6, AW6, "") | BC6: =IF(4<=$G6, ROUND(BB6*$Q6, 2), "") | BD6: =IF(4<=$G6, $N6, "") | BE6: =IF(4<=$G6, BD6-BC6, "") | BF6: =IF(4<=$G6, BB6-BE6, "") | BG6: =IF(4<=$G6, ROUND(AY6*$Q6, 2), "") | BH6: =IF(4<=$G6, AY6+BG6, "") | BI6: =IF(4<=$G6, BC6+BG6, "") | BJ6: =IF(4<=$G6, ($G6-4)*$N6, "") | BK6: =IF(5<=$G6, BF6, "") | BL6: =IF(5<=$G6, ROUND(BK6*$Q6, 2), "") | BM6: =IF(5<=$G6, $N6, "") | BN6: =IF(5<=$G6, BM6-BL6, "") | BO6: =IF(5<=$G6, BK6-BN6, "") | BP6: =IF(5<=$G6, ROUND(BH6*$Q6, 2), "") | BQ6: =IF(5<=$G6, BH6+BP6, "") | BR6: =IF(5<=$G6, BL6+BP6, "") | BS6: =IF(5<=$G6, ($G6-5)*$N6, "") | BT6: =IF(6<=$G6, BO6, "") | BU6: =IF(6<=$G6, ROUND(BT6*$Q6, 2), "") | BV6: =IF(6<=$G6, $N6, "") | BW6: =IF(6<=$G6, BV6-BU6, "") | BX6: =IF(6<=$G6, BT6-BW6, "") | BY6: =IF(6<=$G6, ROUND(BQ6*$Q6, 2), "") | BZ6: =IF(6<=$G6, BQ6+BY6, "") | CA6: =IF(6<=$G6, BU6+BY6, "") | CB6: =IF(6<=$G6, ($G6-6)*$N6, "") | CC6: =IF(7<=$G6, BX6, "") | CD6: =IF(7<=$G6, ROUND(CC6*$Q6, 2), "") | CE6: =IF(7<=$G6, $N6, "") | CF6: =IF(7<=$G6, CE6-CD6, "") | CG6: =IF(7<=$G6, CC6-CF6, "") | CH6: =IF(7<=$G6, ROUND(BZ6*$Q6, 2), "") | CI6: =IF(7<=$G6, BZ6+CH6, "") | CJ6: =IF(7<=$G6, CD6+CH6, "") | CK6: =IF(7<=$G6, ($G6-7)*$N6, "") | CL6: =IF(8<=$G6, CG6, "") | CM6: =IF(8<=$G6, ROUND(CL6*$Q6, 2), "") | CN6: =IF(8<=$G6, $N6, "") | CO6: =IF(8<=$G6, CN6-CM6, "") | CP6: =IF(8<=$G6, CL6-CO6, "") | CQ6: =IF(8<=$G6, ROUND(CI6*$Q6, 2), "") | CR6: =IF(8<=$G6, CI6+CQ6, "") | CS6: =IF(8<=$G6, CM6+CQ6, "") | CT6: =IF(8<=$G6, ($G6-8)*$N6, "") | CU6: =IF(9<=$G6, CP6, "") | CV6: =IF(9<=$G6, ROUND(CU6*$Q6, 2), "") | CW6: =IF(9<=$G6, $N6, "") | CX6: =IF(9<=$G6, CW6-CV6, "") | CY6: =IF(9<=$G6, CU6-CX6, "") | CZ6: =IF(9<=$G6, ROUND(CR6*$Q6, 2), "") | DA6: =IF(9<=$G6, CR6+CZ6, "") | DB6: =IF(9<=$G6, CV6+CZ6, "") | DC6: =IF(9<=$G6, ($G6-9)*$N6, "") | DD6: =IF(10<=$G6, CY6, "") | DE6: =IF(10<=$G6, ROUND(DD6*$Q6, 2), "") | DF6: =IF(10<=$G6, $N6, "") | DG6: =IF(10<=$G6, DF6-DE6, "") | DH6: =IF(10<=$G6, DD6-DG6, "") | DI6: =IF(10<=$G6, ROUND(DA6*$Q6, 2), "") | DJ6: =IF(10<=$G6, DA6+DI6, "") | DK6: =IF(10<=$G6, DE6+DI6, "") | DL6: =IF(10<=$G6, ($G6-10)*$N6, "") | DM6: =IF(11<=$G6, DH6, "") | DN6: =IF(11<=$G6, ROUND(DM6*$Q6, 2), "") | DO6: =IF(11<=$G6, $N6, "") | DP6: =IF(11<=$G6, DO6-DN6, "") | DQ6: =IF(11<=$G6, DM6-DP6, "") | DR6: =IF(11<=$G6, ROUND(DJ6*$Q6, 2), "") | DS6: =IF(11<=$G6, DJ6+DR6, "") | DT6: =IF(11<=$G6, DN6+DR6, "") | DU6: =IF(11<=$G6, ($G6-11)*$N6, "") | DV6: =IF(12<=$G6, DQ6, "") | DW6: =IF(12<=$G6, ROUND(DV6*$Q6, 2), "") | DX6: =IF(12<=$G6, $N6, "") | DY6: =IF(12<=$G6, DX6-DW6, "") | DZ6: =IF(12<=$G6, DV6-DY6, "") | EA6: =IF(12<=$G6, ROUND(DS6*$Q6, 2), "") | EB6: =IF(12<=$G6, DS6+EA6, "") | EC6: =IF(12<=$G6, DW6+EA6, "") | ED6: =IF(12<=$G6, ($G6-12)*$N6, "") | EE6: =IF(13<=$G6, DZ6, "") | EF6: =IF(13<=$G6, ROUND(EE6*$Q6, 2), "") | EG6: =IF(13<=$G6, $N6, "") | EH6: =IF(13<=$G6, EG6-EF6, "") | EI6: =IF(13<=$G6, EE6-EH6, "") | EJ6: =IF(13<=$G6, ROUND(EB6*$Q6, 2), "") | EK6: =IF(13<=$G6, EB6+EJ6, "") | EL6: =IF(13<=$G6, EF6+EJ6, "") | EM6: =IF(13<=$G6, ($G6-13)*$N6, "") | EN6: =IF(14<=$G6, EI6, "") | EO6: =IF(14<=$G6, ROUND(EN6*$Q6, 2), "") | EP6: =IF(14<=$G6, $N6, "") | EQ6: =IF(14<=$G6, EP6-EO6, "") | ER6: =IF(14<=$G6, EN6-EQ6, "") | ES6: =IF(14<=$G6, ROUND(EK6*$Q6, 2), "") | ET6: =IF(14<=$G6, EK6+ES6, "") | EU6: =IF(14<=$G6, EO6+ES6, "") | EV6: =IF(14<=$G6, ($G6-14)*$N6, "") | EW6: =IF(15<=$G6, ER6, "") | EX6: =IF(15<=$G6, ROUND(EW6*$Q6, 2), "") | EY6: =IF(15<=$G6, $N6, "") | EZ6: =IF(15<=$G6, EY6-EX6, "") | FA6: =IF(15<=$G6, EW6-EZ6, "") | FB6: =IF(15<=$G6, ROUND(ET6*$Q6, 2), "") | FC6: =IF(15<=$G6, ET6+FB6, "") | FD6: =IF(15<=$G6, EX6+FB6, "") | FE6: =IF(15<=$G6, ($G6-15)*$N6, "") | FF6: =IF(16<=$G6, FA6, "") | FG6: =IF(16<=$G6, ROUND(FF6*$Q6, 2), "") | FH6: =IF(16<=$G6, $N6, "") | FI6: =IF(16<=$G6, FH6-FG6, "") | FJ6: =IF(16<=$G6, FF6-FI6, "") | FK6: =IF(16<=$G6, ROUND(FC6*$Q6, 2), "") | FL6: =IF(16<=$G6, FC6+FK6, "") | FM6: =IF(16<=$G6, FG6+FK6, "") | FN6: =IF(16<=$G6, ($G6-16)*$N6, "") | FO6: =IF(17<=$G6, FJ6, "") | FP6: =IF(17<=$G6, ROUND(FO6*$Q6, 2), "") | FQ6: =IF(17<=$G6, $N6, "") | FR6: =IF(17<=$G6, FQ6-FP6, "") | FS6: =IF(17<=$G6, FO6-FR6, "") | FT6: =IF(17<=$G6, ROUND(FL6*$Q6, 2), "") | FU6: =IF(17<=$G6, FL6+FT6, "") | FV6: =IF(17<=$G6, FP6+FT6, "") | FW6: =IF(17<=$G6, ($G6-17)*$N6, "") | FX6: =IF(18<=$G6, FS6, "") | FY6: =IF(18<=$G6, ROUND(FX6*$Q6, 2), "") | FZ6: =IF(18<=$G6, $N6, "") | GA6: =IF(18<=$G6, FZ6-FY6, "") | GB6: =IF(18<=$G6, FX6-GA6, "") | GC6: =IF(18<=$G6, ROUND(FU6*$Q6, 2), "") | GD6: =IF(18<=$G6, FU6+GC6, "") | GE6: =IF(18<=$G6, FY6+GC6, "") | GF6: =IF(18<=$G6, ($G6-18)*$N6, "") | GG6: =IF(19<=$G6, GB6, "") | GH6: =IF(19<=$G6, ROUND(GG6*$Q6, 2), "") | GI6: =IF(19<=$G6, $N6, "") | GJ6: =IF(19<=$G6, GI6-GH6, "") | GK6: =IF(19<=$G6, GG6-GJ6, "") | GL6: =IF(19<=$G6, ROUND(GD6*$Q6, 2), "") | GM6: =IF(19<=$G6, GD6+GL6, "") | GN6: =IF(19<=$G6, GH6+GL6, "") | GO6: =IF(19<=$G6, ($G6-19)*$N6, "") | GP6: =IF(20<=$G6, GK6, "") | GQ6: =IF(20<=$G6, ROUND(GP6*$Q6, 2), "") | GR6: =IF(20<=$G6, $N6, "") | GS6: =IF(20<=$G6, GR6-GQ6, "") | GT6: =IF(20<=$G6, GP6-GS6, "") | GU6: =IF(20<=$G6, ROUND(GM6*$Q6, 2), "") | GV6: =IF(20<=$G6, GM6+GU6, "") | GW6: =IF(20<=$G6, GQ6+GU6, "") | GX6: =IF(20<=$G6, ($G6-20)*$N6, "") | GY6: =IF(21<=$G6, GT6, "") | GZ6: =IF(21<=$G6, ROUND(GY6*$Q6, 2), "") | HA6: =IF(21<=$G6, $N6, "") | HB6: =IF(21<=$G6, HA6-GZ6, "") | HC6: =IF(21<=$G6, GY6-HB6, "") | HD6: =IF(21<=$G6, ROUND(GV6*$Q6, 2), "") | HE6: =IF(21<=$G6, GV6+HD6, "") | HF6: =IF(21<=$G6, GZ6+HD6, "") | HG6: =IF(21<=$G6, ($G6-21)*$N6, "") | HH6: =IF(22<=$G6, HC6, "") | HI6: =IF(22<=$G6, ROUND(HH6*$Q6, 2), "") | HJ6: =IF(22<=$G6, $N6, "") | HK6: =IF(22<=$G6, HJ6-HI6, "") | HL6: =IF(22<=$G6, HH6-HK6, "") | HM6: =IF(22<=$G6, ROUND(HE6*$Q6, 2), "") | HN6: =IF(22<=$G6, HE6+HM6, "") | HO6: =IF(22<=$G6, HI6+HM6, "") | HP6: =IF(22<=$G6, ($G6-22)*$N6, "") | HQ6: =IF(23<=$G6, HL6, "") | HR6: =IF(23<=$G6, ROUND(HQ6*$Q6, 2), "") | HS6: =IF(23<=$G6, $N6, "") | HT6: =IF(23<=$G6, HS6-HR6, "") | HU6: =IF(23<=$G6, HQ6-HT6, "") | HV6: =IF(23<=$G6, ROUND(HN6*$Q6, 2), "") | HW6: =IF(23<=$G6, HN6+HV6, "") | HX6: =IF(23<=$G6, HR6+HV6, "") | HY6: =IF(23<=$G6, ($G6-23)*$N6, "") | HZ6: =IF(24<=$G6, HU6, "") | IA6: =IF(24<=$G6, ROUND(HZ6*$Q6, 2), "") | IB6: =IF(24<=$G6, $N6, "") | IC6: =IF(24<=$G6, IB6-IA6, "") | ID6: =IF(24<=$G6, HZ6-IC6, "") | IE6: =IF(24<=$G6, ROUND(HW6*$Q6, 2), "") | IF6: =IF(24<=$G6, HW6+IE6, "") | IG6: =IF(24<=$G6, IA6+IE6, "") | IH6: =IF(24<=$G6, ($G6-24)*$N6, "") | II6: =IF(25<=$G6, ID6, "") | IJ6: =IF(25<=$G6, ROUND(II6*$Q6, 2), "") | IK6: =IF(25<=$G6, $N6, "") | IL6: =IF(25<=$G6, IK6-IJ6, "") | IM6: =IF(25<=$G6, II6-IL6, "") | IN6: =IF(25<=$G6, ROUND(IF6*$Q6, 2), "") | IO6: =IF(25<=$G6, IF6+IN6, "") | IP6: =IF(25<=$G6, IJ6+IN6, "") | IQ6: =IF(25<=$G6, ($G6-25)*$N6, "") | IR6: =IF(26<=$G6, IM6, "") | IS6: =IF(26<=$G6, ROUND(IR6*$Q6, 2), "") | IT6: =IF(26<=$G6, $N6, "") | IU6: =IF(26<=$G6, IT6-IS6, "") | IV6: =IF(26<=$G6, IR6-IU6, "") | IW6: =IF(26<=$G6, ROUND(IO6*$Q6, 2), "") | IX6: =IF(26<=$G6, IO6+IW6, "") | IY6: =IF(26<=$G6, IS6+IW6, "") | IZ6: =IF(26<=$G6, ($G6-26)*$N6, "") | JA6: =IF(27<=$G6, IV6, "") | JB6: =IF(27<=$G6, ROUND(JA6*$Q6, 2), "") | JC6: =IF(27<=$G6, $N6, "") | JD6: =IF(27<=$G6, JC6-JB6, "") | JE6: =IF(27<=$G6, JA6-JD6, "") | JF6: =IF(27<=$G6, ROUND(IX6*$Q6, 2), "") | JG6: =IF(27<=$G6, IX6+JF6, "") | JH6: =IF(27<=$G6, JB6+JF6, "") | JI6: =IF(27<=$G6, ($G6-27)*$N6, "") | JJ6: =IF(28<=$G6, JE6, "") | JK6: =IF(28<=$G6, ROUND(JJ6*$Q6, 2), "") | JL6: =IF(28<=$G6, $N6, "") | JM6: =IF(28<=$G6, JL6-JK6, "") | JN6: =IF(28<=$G6, JJ6-JM6, "") | JO6: =IF(28<=$G6, ROUND(JG6*$Q6, 2), "") | JP6: =IF(28<=$G6, JG6+JO6, "") | JQ6: =IF(28<=$G6, JK6+JO6, "") | JR6: =IF(28<=$G6, ($G6-28)*$N6, "") | JS6: =IF(29<=$G6, JN6, "") | JT6: =IF(29<=$G6, ROUND(JS6*$Q6, 2), "") | JU6: =IF(29<=$G6, $N6, "") | JV6: =IF(29<=$G6, JU6-JT6, "") | JW6: =IF(29<=$G6, JS6-JV6, "") | JX6: =IF(29<=$G6, ROUND(JP6*$Q6, 2), "") | JY6: =IF(29<=$G6, JP6+JX6, "") | JZ6: =IF(29<=$G6, JT6+JX6, "") | KA6: =IF(29<=$G6, ($G6-29)*$N6, "") | KB6: =IF(30<=$G6, JW6, "") | KC6: =IF(30<=$G6, ROUND(KB6*$Q6, 2), "") | KD6: =IF(30<=$G6, $N6, "") | KE6: =IF(30<=$G6, KD6-KC6, "") | KF6: =IF(30<=$G6, KB6-KE6, "") | KG6: =IF(30<=$G6, ROUND(JY6*$Q6, 2), "") | KH6: =IF(30<=$G6, JY6+KG6, "") | KI6: =IF(30<=$G6, KC6+KG6, "") | KJ6: =IF(30<=$G6, ($G6-30)*$N6, "") | KK6: =IF(31<=$G6, KF6, "") | KL6: =IF(31<=$G6, ROUND(KK6*$Q6, 2), "") | KM6: =IF(31<=$G6, $N6, "") | KN6: =IF(31<=$G6, KM6-KL6, "") | KO6: =IF(31<=$G6, KK6-KN6, "") | KP6: =IF(31<=$G6, ROUND(KH6*$Q6, 2), "") | KQ6: =IF(31<=$G6, KH6+KP6, "") | KR6: =IF(31<=$G6, KL6+KP6, "") | KS6: =IF(31<=$G6, ($G6-31)*$N6, "") | KT6: =IF(32<=$G6, KO6, "") | KU6: =IF(32<=$G6, ROUND(KT6*$Q6, 2), "") | KV6: =IF(32<=$G6, $N6, "") | KW6: =IF(32<=$G6, KV6-KU6, "") | KX6: =IF(32<=$G6, KT6-KW6, "") | KY6: =IF(32<=$G6, ROUND(KQ6*$Q6, 2), "") | KZ6: =IF(32<=$G6, KQ6+KY6, "") | LA6: =IF(32<=$G6, KU6+KY6, "") | LB6: =IF(32<=$G6, ($G6-32)*$N6, "") | LC6: =IF(33<=$G6, KX6, "") | LD6: =IF(33<=$G6, ROUND(LC6*$Q6, 2), "") | LE6: =IF(33<=$G6, $N6, "") | LF6: =IF(33<=$G6, LE6-LD6, "") | LG6: =IF(33<=$G6, LC6-LF6, "") | LH6: =IF(33<=$G6, ROUND(KZ6*$Q6, 2), "") | LI6: =IF(33<=$G6, KZ6+LH6, "") | LJ6: =IF(33<=$G6, LD6+LH6, "") | LK6: =IF(33<=$G6, ($G6-33)*$N6, "") | LL6: =IF(34<=$G6, LG6, "") | LM6: =IF(34<=$G6, ROUND(LL6*$Q6, 2), "") | LN6: =IF(34<=$G6, $N6, "") | LO6: =IF(34<=$G6, LN6-LM6, "") | LP6: =IF(34<=$G6, LL6-LO6, "") | LQ6: =IF(34<=$G6, ROUND(LI6*$Q6, 2), "") | LR6: =IF(34<=$G6, LI6+LQ6, "") | LS6: =IF(34<=$G6, LM6+LQ6, "") | LT6: =IF(34<=$G6, ($G6-34)*$N6, "") | LU6: =IF(35<=$G6, LP6, "") | LV6: =IF(35<=$G6, ROUND(LU6*$Q6, 2), "") | LW6: =IF(35<=$G6, $N6, "") | LX6: =IF(35<=$G6, LW6-LV6, "") | LY6: =IF(35<=$G6, LU6-LX6, "") | LZ6: =IF(35<=$G6, ROUND(LR6*$Q6, 2), "") | MA6: =IF(35<=$G6, LR6+LZ6, "") | MB6: =IF(35<=$G6, LV6+LZ6, "") | MC6: =IF(35<=$G6, ($G6-35)*$N6, "") | MD6: =IF(36<=$G6, LY6, "") | ME6: =IF(36<=$G6, ROUND(MD6*$Q6, 2), "") | MF6: =IF(36<=$G6, $N6, "") | MG6: =IF(36<=$G6, MF6-ME6, "") | MH6: =IF(36<=$G6, MD6-MG6, "") | MI6: =IF(36<=$G6, ROUND(MA6*$Q6, 2), "") | MJ6: =IF(36<=$G6, MA6+MI6, "") | MK6: =IF(36<=$G6, ME6+MI6, "") | ML6: =IF(36<=$G6, ($G6-36)*$N6, "") | MM6: =IF(37<=$G6, MH6, "") | MN6: =IF(37<=$G6, ROUND(MM6*$Q6, 2), "") | MO6: =IF(37<=$G6, $N6, "") | MP6: =IF(37<=$G6, MO6-MN6, "") | MQ6: =IF(37<=$G6, MM6-MP6, "") | MR6: =IF(37<=$G6, ROUND(MJ6*$Q6, 2), "") | MS6: =IF(37<=$G6, MJ6+MR6, "") | MT6: =IF(37<=$G6, MN6+MR6, "") | MU6: =IF(37<=$G6, ($G6-37)*$N6, "") | MV6: =IF(38<=$G6, MQ6, "") | MW6: =IF(38<=$G6, ROUND(MV6*$Q6, 2), "") | MX6: =IF(38<=$G6, $N6, "") | MY6: =IF(38<=$G6, MX6-MW6, "") | MZ6: =IF(38<=$G6, MV6-MY6, "") | NA6: =IF(38<=$G6, ROUND(MS6*$Q6, 2), "") | NB6: =IF(38<=$G6, MS6+NA6, "") | NC6: =IF(38<=$G6, MW6+NA6, "") | ND6: =IF(38<=$G6, ($G6-38)*$N6, "") | NE6: =IF(39<=$G6, MZ6, "") | NF6: =IF(39<=$G6, ROUND(NE6*$Q6, 2), "") | NG6: =IF(39<=$G6, $N6, "") | NH6: =IF(39<=$G6, NG6-NF6, "") | NI6: =IF(39<=$G6, NE6-NH6, "") | NJ6: =IF(39<=$G6, ROUND(NB6*$Q6, 2), "") | NK6: =IF(39<=$G6, NB6+NJ6, "") | NL6: =IF(39<=$G6, NF6+NJ6, "") | NM6: =IF(39<=$G6, ($G6-39)*$N6, "") | NN6: =IF(40<=$G6, NI6, "") | NO6: =IF(40<=$G6, ROUND(NN6*$Q6, 2), "") | NP6: =IF(40<=$G6, $N6, "") | NQ6: =IF(40<=$G6, NP6-NO6, "") | NR6: =IF(40<=$G6, NN6-NQ6, "") | NS6: =IF(40<=$G6, ROUND(NK6*$Q6, 2), "") | NT6: =IF(40<=$G6, NK6+NS6, "") | NU6: =IF(40<=$G6, NO6+NS6, "") | NV6: =IF(40<=$G6, ($G6-40)*$N6, "") | NW6: =IF(41<=$G6, NR6, "") | NX6: =IF(41<=$G6, ROUND(NW6*$Q6, 2), "") | NY6: =IF(41<=$G6, $N6, "") | NZ6: =IF(41<=$G6, NY6-NX6, "") | OA6: =IF(41<=$G6, NW6-NZ6, "") | OB6: =IF(41<=$G6, ROUND(NT6*$Q6, 2), "") | OC6: =IF(41<=$G6, NT6+OB6, "") | OD6: =IF(41<=$G6, NX6+OB6, "") | OE6: =IF(41<=$G6, ($G6-41)*$N6, "") | OF6: =IF(42<=$G6, OA6, "") | OG6: =IF(42<=$G6, ROUND(OF6*$Q6, 2), "") | OH6: =IF(42<=$G6, $N6, "") | OI6: =IF(42<=$G6, OH6-OG6, "") | OJ6: =IF(42<=$G6, OF6-OI6, "") | OK6: =IF(42<=$G6, ROUND(OC6*$Q6, 2), "") | OL6: =IF(42<=$G6, OC6+OK6, "") | OM6: =IF(42<=$G6, OG6+OK6, "") | ON6: =IF(42<=$G6, ($G6-42)*$N6, "") | OO6: =IF(43<=$G6, OJ6, "") | OP6: =IF(43<=$G6, ROUND(OO6*$Q6, 2), "") | OQ6: =IF(43<=$G6, $N6, "") | OR6: =IF(43<=$G6, OQ6-OP6, "") | OS6: =IF(43<=$G6, OO6-OR6, "") | OT6: =IF(43<=$G6, ROUND(OL6*$Q6, 2), "") | OU6: =IF(43<=$G6, OL6+OT6, "") | OV6: =IF(43<=$G6, OP6+OT6, "") | OW6: =IF(43<=$G6, ($G6-43)*$N6, "") | OX6: =IF(44<=$G6, OS6, "") | OY6: =IF(44<=$G6, ROUND(OX6*$Q6, 2), "") | OZ6: =IF(44<=$G6, $N6, "") | PA6: =IF(44<=$G6, OZ6-OY6, "") | PB6: =IF(44<=$G6, OX6-PA6, "") | PC6: =IF(44<=$G6, ROUND(OU6*$Q6, 2), "") | PD6: =IF(44<=$G6, OU6+PC6, "") | PE6: =IF(44<=$G6, OY6+PC6, "") | PF6: =IF(44<=$G6, ($G6-44)*$N6, "") | PG6: =IF(45<=$G6, PB6, "") | PH6: =IF(45<=$G6, ROUND(PG6*$Q6, 2), "") | PI6: =IF(45<=$G6, $N6, "") | PJ6: =IF(45<=$G6, PI6-PH6, "") | PK6: =IF(45<=$G6, PG6-PJ6, "") | PL6: =IF(45<=$G6, ROUND(PD6*$Q6, 2), "") | PM6: =IF(45<=$G6, PD6+PL6, "") | PN6: =IF(45<=$G6, PH6+PL6, "") | PO6: =IF(45<=$G6, ($G6-45)*$N6, "") | PP6: =IF(46<=$G6, PK6, "") | PQ6: =IF(46<=$G6, ROUND(PP6*$Q6, 2), "") | PR6: =IF(46<=$G6, $N6, "") | PS6: =IF(46<=$G6, PR6-PQ6, "") | PT6: =IF(46<=$G6, PP6-PS6, "") | PU6: =IF(46<=$G6, ROUND(PM6*$Q6, 2), "") | PV6: =IF(46<=$G6, PM6+PU6, "") | PW6: =IF(46<=$G6, PQ6+PU6, "") | PX6: =IF(46<=$G6, ($G6-46)*$N6, "") | PY6: =IF(47<=$G6, PT6, "") | PZ6: =IF(47<=$G6, ROUND(PY6*$Q6, 2), "") | QA6: =IF(47<=$G6, $N6, "") | QB6: =IF(47<=$G6, QA6-PZ6, "") | QC6: =IF(47<=$G6, PY6-QB6, "") | QD6: =IF(47<=$G6, ROUND(PV6*$Q6, 2), "") | QE6: =IF(47<=$G6, PV6+QD6, "") | QF6: =IF(47<=$G6, PZ6+QD6, "") | QG6: =IF(47<=$G6, ($G6-47)*$N6, "") | QH6: =IF(48<=$G6, QC6, "") | QI6: =IF(48<=$G6, ROUND(QH6*$Q6, 2), "") | QJ6: =IF(48<=$G6, $N6, "") | QK6: =IF(48<=$G6, QJ6-QI6, "") | QL6: =IF(48<=$G6, QH6-QK6, "") | QM6: =IF(48<=$G6, ROUND(QE6*$Q6, 2), "") | QN6: =IF(48<=$G6, QE6+QM6, "") | QO6: =IF(48<=$G6, QI6+QM6, "") | QP6: =IF(48<=$G6, ($G6-48)*$N6, "")
A7: 0504-0004 | B7: Oscar Ivan Lozano Terriquez | C7: 700 BIGHORN "S" CREW CAB MT | D7: ACTIVO | E7: 2026-01-05 | F7: 2027-01-05 | G7: 12 | H7: 352500 | I7: 0.35 | J7: =ROUND(H7*I7, 2) | K7: =ROUND(H7-J7, 2) | L7: 0.02 | M7: =ROUND(H7*L7, 2) | N7: 19654.64 | O7: 0.1 | P7: =ROUND(H7*O7, 2) | Q7: 0.02415117 | R7: =RATE(G7, -N7, K7, -P7) | S7: =ROUND(Q7*12, 8) | T7: =ROUND(((1+Q7)^12)-1, 8) | U7: =ROUND(PV(Q7, G7, 0, -P7), 2) | V7: =SUMIF($AA$4:$QP$4, "Interes_Leasing", AA7:QP7) | W7: =SUMIF($AA$4:$QP$4, "Interes_Residual", AA7:QP7) | X7: =ROUND(V7+W7, 2) | Y7: =ROUND((N7*G7+P7+M7)-K7, 2) | Z7: =ROUND(Y7/K7, 4) | AA7: =IF(1<=$G7, $K7, "") | AB7: =IF(1<=$G7, ROUND(AA7*$Q7, 2), "") | AC7: =IF(1<=$G7, $N7, "") | AD7: =IF(1<=$G7, AC7-AB7, "") | AE7: =IF(1<=$G7, AA7-AD7, "") | AF7: =IF(1<=$G7, ROUND($U7*$Q7, 2), "") | AG7: =IF(1<=$G7, $U7+AF7, "") | AH7: =IF(1<=$G7, AB7+AF7, "") | AI7: =IF(1<=$G7, ($G7-1)*$N7, "") | AJ7: =IF(2<=$G7, AE7, "") | AK7: =IF(2<=$G7, ROUND(AJ7*$Q7, 2), "") | AL7: =IF(2<=$G7, $N7, "") | AM7: =IF(2<=$G7, AL7-AK7, "") | AN7: =IF(2<=$G7, AJ7-AM7, "") | AO7: =IF(2<=$G7, ROUND(AG7*$Q7, 2), "") | AP7: =IF(2<=$G7, AG7+AO7, "") | AQ7: =IF(2<=$G7, AK7+AO7, "") | AR7: =IF(2<=$G7, ($G7-2)*$N7, "") | AS7: =IF(3<=$G7, AN7, "") | AT7: =IF(3<=$G7, ROUND(AS7*$Q7, 2), "") | AU7: =IF(3<=$G7, $N7, "") | AV7: =IF(3<=$G7, AU7-AT7, "") | AW7: =IF(3<=$G7, AS7-AV7, "") | AX7: =IF(3<=$G7, ROUND(AP7*$Q7, 2), "") | AY7: =IF(3<=$G7, AP7+AX7, "") | AZ7: =IF(3<=$G7, AT7+AX7, "") | BA7: =IF(3<=$G7, ($G7-3)*$N7, "") | BB7: =IF(4<=$G7, AW7, "") | BC7: =IF(4<=$G7, ROUND(BB7*$Q7, 2), "") | BD7: =IF(4<=$G7, $N7, "") | BE7: =IF(4<=$G7, BD7-BC7, "") | BF7: =IF(4<=$G7, BB7-BE7, "") | BG7: =IF(4<=$G7, ROUND(AY7*$Q7, 2), "") | BH7: =IF(4<=$G7, AY7+BG7, "") | BI7: =IF(4<=$G7, BC7+BG7, "") | BJ7: =IF(4<=$G7, ($G7-4)*$N7, "") | BK7: =IF(5<=$G7, BF7, "") | BL7: =IF(5<=$G7, ROUND(BK7*$Q7, 2), "") | BM7: =IF(5<=$G7, $N7, "") | BN7: =IF(5<=$G7, BM7-BL7, "") | BO7: =IF(5<=$G7, BK7-BN7, "") | BP7: =IF(5<=$G7, ROUND(BH7*$Q7, 2), "") | BQ7: =IF(5<=$G7, BH7+BP7, "") | BR7: =IF(5<=$G7, BL7+BP7, "") | BS7: =IF(5<=$G7, ($G7-5)*$N7, "") | BT7: =IF(6<=$G7, BO7, "") | BU7: =IF(6<=$G7, ROUND(BT7*$Q7, 2), "") | BV7: =IF(6<=$G7, $N7, "") | BW7: =IF(6<=$G7, BV7-BU7, "") | BX7: =IF(6<=$G7, BT7-BW7, "") | BY7: =IF(6<=$G7, ROUND(BQ7*$Q7, 2), "") | BZ7: =IF(6<=$G7, BQ7+BY7, "") | CA7: =IF(6<=$G7, BU7+BY7, "") | CB7: =IF(6<=$G7, ($G7-6)*$N7, "") | CC7: =IF(7<=$G7, BX7, "") | CD7: =IF(7<=$G7, ROUND(CC7*$Q7, 2), "") | CE7: =IF(7<=$G7, $N7, "") | CF7: =IF(7<=$G7, CE7-CD7, "") | CG7: =IF(7<=$G7, CC7-CF7, "") | CH7: =IF(7<=$G7, ROUND(BZ7*$Q7, 2), "") | CI7: =IF(7<=$G7, BZ7+CH7, "") | CJ7: =IF(7<=$G7, CD7+CH7, "") | CK7: =IF(7<=$G7, ($G7-7)*$N7, "") | CL7: =IF(8<=$G7, CG7, "") | CM7: =IF(8<=$G7, ROUND(CL7*$Q7, 2), "") | CN7: =IF(8<=$G7, $N7, "") | CO7: =IF(8<=$G7, CN7-CM7, "") | CP7: =IF(8<=$G7, CL7-CO7, "") | CQ7: =IF(8<=$G7, ROUND(CI7*$Q7, 2), "") | CR7: =IF(8<=$G7, CI7+CQ7, "") | CS7: =IF(8<=$G7, CM7+CQ7, "") | CT7: =IF(8<=$G7, ($G7-8)*$N7, "") | CU7: =IF(9<=$G7, CP7, "") | CV7: =IF(9<=$G7, ROUND(CU7*$Q7, 2), "") | CW7: =IF(9<=$G7, $N7, "") | CX7: =IF(9<=$G7, CW7-CV7, "") | CY7: =IF(9<=$G7, CU7-CX7, "") | CZ7: =IF(9<=$G7, ROUND(CR7*$Q7, 2), "") | DA7: =IF(9<=$G7, CR7+CZ7, "") | DB7: =IF(9<=$G7, CV7+CZ7, "") | DC7: =IF(9<=$G7, ($G7-9)*$N7, "") | DD7: =IF(10<=$G7, CY7, "") | DE7: =IF(10<=$G7, ROUND(DD7*$Q7, 2), "") | DF7: =IF(10<=$G7, $N7, "") | DG7: =IF(10<=$G7, DF7-DE7, "") | DH7: =IF(10<=$G7, DD7-DG7, "") | DI7: =IF(10<=$G7, ROUND(DA7*$Q7, 2), "") | DJ7: =IF(10<=$G7, DA7+DI7, "") | DK7: =IF(10<=$G7, DE7+DI7, "") | DL7: =IF(10<=$G7, ($G7-10)*$N7, "") | DM7: =IF(11<=$G7, DH7, "") | DN7: =IF(11<=$G7, ROUND(DM7*$Q7, 2), "") | DO7: =IF(11<=$G7, $N7, "") | DP7: =IF(11<=$G7, DO7-DN7, "") | DQ7: =IF(11<=$G7, DM7-DP7, "") | DR7: =IF(11<=$G7, ROUND(DJ7*$Q7, 2), "") | DS7: =IF(11<=$G7, DJ7+DR7, "") | DT7: =IF(11<=$G7, DN7+DR7, "") | DU7: =IF(11<=$G7, ($G7-11)*$N7, "") | DV7: =IF(12<=$G7, DQ7, "") | DW7: =IF(12<=$G7, ROUND(DV7*$Q7, 2), "") | DX7: =IF(12<=$G7, $N7, "") | DY7: =IF(12<=$G7, DX7-DW7, "") | DZ7: =IF(12<=$G7, DV7-DY7, "") | EA7: =IF(12<=$G7, ROUND(DS7*$Q7, 2), "") | EB7: =IF(12<=$G7, DS7+EA7, "") | EC7: =IF(12<=$G7, DW7+EA7, "") | ED7: =IF(12<=$G7, ($G7-12)*$N7, "") | EE7: =IF(13<=$G7, DZ7, "") | EF7: =IF(13<=$G7, ROUND(EE7*$Q7, 2), "") | EG7: =IF(13<=$G7, $N7, "") | EH7: =IF(13<=$G7, EG7-EF7, "") | EI7: =IF(13<=$G7, EE7-EH7, "") | EJ7: =IF(13<=$G7, ROUND(EB7*$Q7, 2), "") | EK7: =IF(13<=$G7, EB7+EJ7, "") | EL7: =IF(13<=$G7, EF7+EJ7, "") | EM7: =IF(13<=$G7, ($G7-13)*$N7, "") | EN7: =IF(14<=$G7, EI7, "") | EO7: =IF(14<=$G7, ROUND(EN7*$Q7, 2), "") | EP7: =IF(14<=$G7, $N7, "") | EQ7: =IF(14<=$G7, EP7-EO7, "") | ER7: =IF(14<=$G7, EN7-EQ7, "") | ES7: =IF(14<=$G7, ROUND(EK7*$Q7, 2), "") | ET7: =IF(14<=$G7, EK7+ES7, "") | EU7: =IF(14<=$G7, EO7+ES7, "") | EV7: =IF(14<=$G7, ($G7-14)*$N7, "") | EW7: =IF(15<=$G7, ER7, "") | EX7: =IF(15<=$G7, ROUND(EW7*$Q7, 2), "") | EY7: =IF(15<=$G7, $N7, "") | EZ7: =IF(15<=$G7, EY7-EX7, "") | FA7: =IF(15<=$G7, EW7-EZ7, "") | FB7: =IF(15<=$G7, ROUND(ET7*$Q7, 2), "") | FC7: =IF(15<=$G7, ET7+FB7, "") | FD7: =IF(15<=$G7, EX7+FB7, "") | FE7: =IF(15<=$G7, ($G7-15)*$N7, "") | FF7: =IF(16<=$G7, FA7, "") | FG7: =IF(16<=$G7, ROUND(FF7*$Q7, 2), "") | FH7: =IF(16<=$G7, $N7, "") | FI7: =IF(16<=$G7, FH7-FG7, "") | FJ7: =IF(16<=$G7, FF7-FI7, "") | FK7: =IF(16<=$G7, ROUND(FC7*$Q7, 2), "") | FL7: =IF(16<=$G7, FC7+FK7, "") | FM7: =IF(16<=$G7, FG7+FK7, "") | FN7: =IF(16<=$G7, ($G7-16)*$N7, "") | FO7: =IF(17<=$G7, FJ7, "") | FP7: =IF(17<=$G7, ROUND(FO7*$Q7, 2), "") | FQ7: =IF(17<=$G7, $N7, "") | FR7: =IF(17<=$G7, FQ7-FP7, "") | FS7: =IF(17<=$G7, FO7-FR7, "") | FT7: =IF(17<=$G7, ROUND(FL7*$Q7, 2), "") | FU7: =IF(17<=$G7, FL7+FT7, "") | FV7: =IF(17<=$G7, FP7+FT7, "") | FW7: =IF(17<=$G7, ($G7-17)*$N7, "") | FX7: =IF(18<=$G7, FS7, "") | FY7: =IF(18<=$G7, ROUND(FX7*$Q7, 2), "") | FZ7: =IF(18<=$G7, $N7, "") | GA7: =IF(18<=$G7, FZ7-FY7, "") | GB7: =IF(18<=$G7, FX7-GA7, "") | GC7: =IF(18<=$G7, ROUND(FU7*$Q7, 2), "") | GD7: =IF(18<=$G7, FU7+GC7, "") | GE7: =IF(18<=$G7, FY7+GC7, "") | GF7: =IF(18<=$G7, ($G7-18)*$N7, "") | GG7: =IF(19<=$G7, GB7, "") | GH7: =IF(19<=$G7, ROUND(GG7*$Q7, 2), "") | GI7: =IF(19<=$G7, $N7, "") | GJ7: =IF(19<=$G7, GI7-GH7, "") | GK7: =IF(19<=$G7, GG7-GJ7, "") | GL7: =IF(19<=$G7, ROUND(GD7*$Q7, 2), "") | GM7: =IF(19<=$G7, GD7+GL7, "") | GN7: =IF(19<=$G7, GH7+GL7, "") | GO7: =IF(19<=$G7, ($G7-19)*$N7, "") | GP7: =IF(20<=$G7, GK7, "") | GQ7: =IF(20<=$G7, ROUND(GP7*$Q7, 2), "") | GR7: =IF(20<=$G7, $N7, "") | GS7: =IF(20<=$G7, GR7-GQ7, "") | GT7: =IF(20<=$G7, GP7-GS7, "") | GU7: =IF(20<=$G7, ROUND(GM7*$Q7, 2), "") | GV7: =IF(20<=$G7, GM7+GU7, "") | GW7: =IF(20<=$G7, GQ7+GU7, "") | GX7: =IF(20<=$G7, ($G7-20)*$N7, "") | GY7: =IF(21<=$G7, GT7, "") | GZ7: =IF(21<=$G7, ROUND(GY7*$Q7, 2), "") | HA7: =IF(21<=$G7, $N7, "") | HB7: =IF(21<=$G7, HA7-GZ7, "") | HC7: =IF(21<=$G7, GY7-HB7, "") | HD7: =IF(21<=$G7, ROUND(GV7*$Q7, 2), "") | HE7: =IF(21<=$G7, GV7+HD7, "") | HF7: =IF(21<=$G7, GZ7+HD7, "") | HG7: =IF(21<=$G7, ($G7-21)*$N7, "") | HH7: =IF(22<=$G7, HC7, "") | HI7: =IF(22<=$G7, ROUND(HH7*$Q7, 2), "") | HJ7: =IF(22<=$G7, $N7, "") | HK7: =IF(22<=$G7, HJ7-HI7, "") | HL7: =IF(22<=$G7, HH7-HK7, "") | HM7: =IF(22<=$G7, ROUND(HE7*$Q7, 2), "") | HN7: =IF(22<=$G7, HE7+HM7, "") | HO7: =IF(22<=$G7, HI7+HM7, "") | HP7: =IF(22<=$G7, ($G7-22)*$N7, "") | HQ7: =IF(23<=$G7, HL7, "") | HR7: =IF(23<=$G7, ROUND(HQ7*$Q7, 2), "") | HS7: =IF(23<=$G7, $N7, "") | HT7: =IF(23<=$G7, HS7-HR7, "") | HU7: =IF(23<=$G7, HQ7-HT7, "") | HV7: =IF(23<=$G7, ROUND(HN7*$Q7, 2), "") | HW7: =IF(23<=$G7, HN7+HV7, "") | HX7: =IF(23<=$G7, HR7+HV7, "") | HY7: =IF(23<=$G7, ($G7-23)*$N7, "") | HZ7: =IF(24<=$G7, HU7, "") | IA7: =IF(24<=$G7, ROUND(HZ7*$Q7, 2), "") | IB7: =IF(24<=$G7, $N7, "") | IC7: =IF(24<=$G7, IB7-IA7, "") | ID7: =IF(24<=$G7, HZ7-IC7, "") | IE7: =IF(24<=$G7, ROUND(HW7*$Q7, 2), "") | IF7: =IF(24<=$G7, HW7+IE7, "") | IG7: =IF(24<=$G7, IA7+IE7, "") | IH7: =IF(24<=$G7, ($G7-24)*$N7, "") | II7: =IF(25<=$G7, ID7, "") | IJ7: =IF(25<=$G7, ROUND(II7*$Q7, 2), "") | IK7: =IF(25<=$G7, $N7, "") | IL7: =IF(25<=$G7, IK7-IJ7, "") | IM7: =IF(25<=$G7, II7-IL7, "") | IN7: =IF(25<=$G7, ROUND(IF7*$Q7, 2), "") | IO7: =IF(25<=$G7, IF7+IN7, "") | IP7: =IF(25<=$G7, IJ7+IN7, "") | IQ7: =IF(25<=$G7, ($G7-25)*$N7, "") | IR7: =IF(26<=$G7, IM7, "") | IS7: =IF(26<=$G7, ROUND(IR7*$Q7, 2), "") | IT7: =IF(26<=$G7, $N7, "") | IU7: =IF(26<=$G7, IT7-IS7, "") | IV7: =IF(26<=$G7, IR7-IU7, "") | IW7: =IF(26<=$G7, ROUND(IO7*$Q7, 2), "") | IX7: =IF(26<=$G7, IO7+IW7, "") | IY7: =IF(26<=$G7, IS7+IW7, "") | IZ7: =IF(26<=$G7, ($G7-26)*$N7, "") | JA7: =IF(27<=$G7, IV7, "") | JB7: =IF(27<=$G7, ROUND(JA7*$Q7, 2), "") | JC7: =IF(27<=$G7, $N7, "") | JD7: =IF(27<=$G7, JC7-JB7, "") | JE7: =IF(27<=$G7, JA7-JD7, "") | JF7: =IF(27<=$G7, ROUND(IX7*$Q7, 2), "") | JG7: =IF(27<=$G7, IX7+JF7, "") | JH7: =IF(27<=$G7, JB7+JF7, "") | JI7: =IF(27<=$G7, ($G7-27)*$N7, "") | JJ7: =IF(28<=$G7, JE7, "") | JK7: =IF(28<=$G7, ROUND(JJ7*$Q7, 2), "") | JL7: =IF(28<=$G7, $N7, "") | JM7: =IF(28<=$G7, JL7-JK7, "") | JN7: =IF(28<=$G7, JJ7-JM7, "") | JO7: =IF(28<=$G7, ROUND(JG7*$Q7, 2), "") | JP7: =IF(28<=$G7, JG7+JO7, "") | JQ7: =IF(28<=$G7, JK7+JO7, "") | JR7: =IF(28<=$G7, ($G7-28)*$N7, "") | JS7: =IF(29<=$G7, JN7, "") | JT7: =IF(29<=$G7, ROUND(JS7*$Q7, 2), "") | JU7: =IF(29<=$G7, $N7, "") | JV7: =IF(29<=$G7, JU7-JT7, "") | JW7: =IF(29<=$G7, JS7-JV7, "") | JX7: =IF(29<=$G7, ROUND(JP7*$Q7, 2), "") | JY7: =IF(29<=$G7, JP7+JX7, "") | JZ7: =IF(29<=$G7, JT7+JX7, "") | KA7: =IF(29<=$G7, ($G7-29)*$N7, "") | KB7: =IF(30<=$G7, JW7, "") | KC7: =IF(30<=$G7, ROUND(KB7*$Q7, 2), "") | KD7: =IF(30<=$G7, $N7, "") | KE7: =IF(30<=$G7, KD7-KC7, "") | KF7: =IF(30<=$G7, KB7-KE7, "") | KG7: =IF(30<=$G7, ROUND(JY7*$Q7, 2), "") | KH7: =IF(30<=$G7, JY7+KG7, "") | KI7: =IF(30<=$G7, KC7+KG7, "") | KJ7: =IF(30<=$G7, ($G7-30)*$N7, "") | KK7: =IF(31<=$G7, KF7, "") | KL7: =IF(31<=$G7, ROUND(KK7*$Q7, 2), "") | KM7: =IF(31<=$G7, $N7, "") | KN7: =IF(31<=$G7, KM7-KL7, "") | KO7: =IF(31<=$G7, KK7-KN7, "") | KP7: =IF(31<=$G7, ROUND(KH7*$Q7, 2), "") | KQ7: =IF(31<=$G7, KH7+KP7, "") | KR7: =IF(31<=$G7, KL7+KP7, "") | KS7: =IF(31<=$G7, ($G7-31)*$N7, "") | KT7: =IF(32<=$G7, KO7, "") | KU7: =IF(32<=$G7, ROUND(KT7*$Q7, 2), "") | KV7: =IF(32<=$G7, $N7, "") | KW7: =IF(32<=$G7, KV7-KU7, "") | KX7: =IF(32<=$G7, KT7-KW7, "") | KY7: =IF(32<=$G7, ROUND(KQ7*$Q7, 2), "") | KZ7: =IF(32<=$G7, KQ7+KY7, "") | LA7: =IF(32<=$G7, KU7+KY7, "") | LB7: =IF(32<=$G7, ($G7-32)*$N7, "") | LC7: =IF(33<=$G7, KX7, "") | LD7: =IF(33<=$G7, ROUND(LC7*$Q7, 2), "") | LE7: =IF(33<=$G7, $N7, "") | LF7: =IF(33<=$G7, LE7-LD7, "") | LG7: =IF(33<=$G7, LC7-LF7, "") | LH7: =IF(33<=$G7, ROUND(KZ7*$Q7, 2), "") | LI7: =IF(33<=$G7, KZ7+LH7, "") | LJ7: =IF(33<=$G7, LD7+LH7, "") | LK7: =IF(33<=$G7, ($G7-33)*$N7, "") | LL7: =IF(34<=$G7, LG7, "") | LM7: =IF(34<=$G7, ROUND(LL7*$Q7, 2), "") | LN7: =IF(34<=$G7, $N7, "") | LO7: =IF(34<=$G7, LN7-LM7, "") | LP7: =IF(34<=$G7, LL7-LO7, "") | LQ7: =IF(34<=$G7, ROUND(LI7*$Q7, 2), "") | LR7: =IF(34<=$G7, LI7+LQ7, "") | LS7: =IF(34<=$G7, LM7+LQ7, "") | LT7: =IF(34<=$G7, ($G7-34)*$N7, "") | LU7: =IF(35<=$G7, LP7, "") | LV7: =IF(35<=$G7, ROUND(LU7*$Q7, 2), "") | LW7: =IF(35<=$G7, $N7, "") | LX7: =IF(35<=$G7, LW7-LV7, "") | LY7: =IF(35<=$G7, LU7-LX7, "") | LZ7: =IF(35<=$G7, ROUND(LR7*$Q7, 2), "") | MA7: =IF(35<=$G7, LR7+LZ7, "") | MB7: =IF(35<=$G7, LV7+LZ7, "") | MC7: =IF(35<=$G7, ($G7-35)*$N7, "") | MD7: =IF(36<=$G7, LY7, "") | ME7: =IF(36<=$G7, ROUND(MD7*$Q7, 2), "") | MF7: =IF(36<=$G7, $N7, "") | MG7: =IF(36<=$G7, MF7-ME7, "") | MH7: =IF(36<=$G7, MD7-MG7, "") | MI7: =IF(36<=$G7, ROUND(MA7*$Q7, 2), "") | MJ7: =IF(36<=$G7, MA7+MI7, "") | MK7: =IF(36<=$G7, ME7+MI7, "") | ML7: =IF(36<=$G7, ($G7-36)*$N7, "") | MM7: =IF(37<=$G7, MH7, "") | MN7: =IF(37<=$G7, ROUND(MM7*$Q7, 2), "") | MO7: =IF(37<=$G7, $N7, "") | MP7: =IF(37<=$G7, MO7-MN7, "") | MQ7: =IF(37<=$G7, MM7-MP7, "") | MR7: =IF(37<=$G7, ROUND(MJ7*$Q7, 2), "") | MS7: =IF(37<=$G7, MJ7+MR7, "") | MT7: =IF(37<=$G7, MN7+MR7, "") | MU7: =IF(37<=$G7, ($G7-37)*$N7, "") | MV7: =IF(38<=$G7, MQ7, "") | MW7: =IF(38<=$G7, ROUND(MV7*$Q7, 2), "") | MX7: =IF(38<=$G7, $N7, "") | MY7: =IF(38<=$G7, MX7-MW7, "") | MZ7: =IF(38<=$G7, MV7-MY7, "") | NA7: =IF(38<=$G7, ROUND(MS7*$Q7, 2), "") | NB7: =IF(38<=$G7, MS7+NA7, "") | NC7: =IF(38<=$G7, MW7+NA7, "") | ND7: =IF(38<=$G7, ($G7-38)*$N7, "") | NE7: =IF(39<=$G7, MZ7, "") | NF7: =IF(39<=$G7, ROUND(NE7*$Q7, 2), "") | NG7: =IF(39<=$G7, $N7, "") | NH7: =IF(39<=$G7, NG7-NF7, "") | NI7: =IF(39<=$G7, NE7-NH7, "") | NJ7: =IF(39<=$G7, ROUND(NB7*$Q7, 2), "") | NK7: =IF(39<=$G7, NB7+NJ7, "") | NL7: =IF(39<=$G7, NF7+NJ7, "") | NM7: =IF(39<=$G7, ($G7-39)*$N7, "") | NN7: =IF(40<=$G7, NI7, "") | NO7: =IF(40<=$G7, ROUND(NN7*$Q7, 2), "") | NP7: =IF(40<=$G7, $N7, "") | NQ7: =IF(40<=$G7, NP7-NO7, "") | NR7: =IF(40<=$G7, NN7-NQ7, "") | NS7: =IF(40<=$G7, ROUND(NK7*$Q7, 2), "") | NT7: =IF(40<=$G7, NK7+NS7, "") | NU7: =IF(40<=$G7, NO7+NS7, "") | NV7: =IF(40<=$G7, ($G7-40)*$N7, "") | NW7: =IF(41<=$G7, NR7, "") | NX7: =IF(41<=$G7, ROUND(NW7*$Q7, 2), "") | NY7: =IF(41<=$G7, $N7, "") | NZ7: =IF(41<=$G7, NY7-NX7, "") | OA7: =IF(41<=$G7, NW7-NZ7, "") | OB7: =IF(41<=$G7, ROUND(NT7*$Q7, 2), "") | OC7: =IF(41<=$G7, NT7+OB7, "") | OD7: =IF(41<=$G7, NX7+OB7, "") | OE7: =IF(41<=$G7, ($G7-41)*$N7, "") | OF7: =IF(42<=$G7, OA7, "") | OG7: =IF(42<=$G7, ROUND(OF7*$Q7, 2), "") | OH7: =IF(42<=$G7, $N7, "") | OI7: =IF(42<=$G7, OH7-OG7, "") | OJ7: =IF(42<=$G7, OF7-OI7, "") | OK7: =IF(42<=$G7, ROUND(OC7*$Q7, 2), "") | OL7: =IF(42<=$G7, OC7+OK7, "") | OM7: =IF(42<=$G7, OG7+OK7, "") | ON7: =IF(42<=$G7, ($G7-42)*$N7, "") | OO7: =IF(43<=$G7, OJ7, "") | OP7: =IF(43<=$G7, ROUND(OO7*$Q7, 2), "") | OQ7: =IF(43<=$G7, $N7, "") | OR7: =IF(43<=$G7, OQ7-OP7, "") | OS7: =IF(43<=$G7, OO7-OR7, "") | OT7: =IF(43<=$G7, ROUND(OL7*$Q7, 2), "") | OU7: =IF(43<=$G7, OL7+OT7, "") | OV7: =IF(43<=$G7, OP7+OT7, "") | OW7: =IF(43<=$G7, ($G7-43)*$N7, "") | OX7: =IF(44<=$G7, OS7, "") | OY7: =IF(44<=$G7, ROUND(OX7*$Q7, 2), "") | OZ7: =IF(44<=$G7, $N7, "") | PA7: =IF(44<=$G7, OZ7-OY7, "") | PB7: =IF(44<=$G7, OX7-PA7, "") | PC7: =IF(44<=$G7, ROUND(OU7*$Q7, 2), "") | PD7: =IF(44<=$G7, OU7+PC7, "") | PE7: =IF(44<=$G7, OY7+PC7, "") | PF7: =IF(44<=$G7, ($G7-44)*$N7, "") | PG7: =IF(45<=$G7, PB7, "") | PH7: =IF(45<=$G7, ROUND(PG7*$Q7, 2), "") | PI7: =IF(45<=$G7, $N7, "") | PJ7: =IF(45<=$G7, PI7-PH7, "") | PK7: =IF(45<=$G7, PG7-PJ7, "") | PL7: =IF(45<=$G7, ROUND(PD7*$Q7, 2), "") | PM7: =IF(45<=$G7, PD7+PL7, "") | PN7: =IF(45<=$G7, PH7+PL7, "") | PO7: =IF(45<=$G7, ($G7-45)*$N7, "") | PP7: =IF(46<=$G7, PK7, "") | PQ7: =IF(46<=$G7, ROUND(PP7*$Q7, 2), "") | PR7: =IF(46<=$G7, $N7, "") | PS7: =IF(46<=$G7, PR7-PQ7, "") | PT7: =IF(46<=$G7, PP7-PS7, "") | PU7: =IF(46<=$G7, ROUND(PM7*$Q7, 2), "") | PV7: =IF(46<=$G7, PM7+PU7, "") | PW7: =IF(46<=$G7, PQ7+PU7, "") | PX7: =IF(46<=$G7, ($G7-46)*$N7, "") | PY7: =IF(47<=$G7, PT7, "") | PZ7: =IF(47<=$G7, ROUND(PY7*$Q7, 2), "") | QA7: =IF(47<=$G7, $N7, "") | QB7: =IF(47<=$G7, QA7-PZ7, "") | QC7: =IF(47<=$G7, PY7-QB7, "") | QD7: =IF(47<=$G7, ROUND(PV7*$Q7, 2), "") | QE7: =IF(47<=$G7, PV7+QD7, "") | QF7: =IF(47<=$G7, PZ7+QD7, "") | QG7: =IF(47<=$G7, ($G7-47)*$N7, "") | QH7: =IF(48<=$G7, QC7, "") | QI7: =IF(48<=$G7, ROUND(QH7*$Q7, 2), "") | QJ7: =IF(48<=$G7, $N7, "") | QK7: =IF(48<=$G7, QJ7-QI7, "") | QL7: =IF(48<=$G7, QH7-QK7, "") | QM7: =IF(48<=$G7, ROUND(QE7*$Q7, 2), "") | QN7: =IF(48<=$G7, QE7+QM7, "") | QO7: =IF(48<=$G7, QI7+QM7, "") | QP7: =IF(48<=$G7, ($G7-48)*$N7, "")
